Workbook

Sheet Podsumowanie
A1: Verris — parytet funkcji wobec rynku
A2: Wygenerowane 2026-10-13 z audyt/dane/macierz.csv · nie edytuj tego pliku ręcznie
A4: Werdykt parytetu
A5: Wartość | B5: Pozycji
A6: PARYTET | B6: =COUNTIF(Macierz!$K$2:$K$441,A6)
A7: PRZEWAGA | B7: =COUNTIF(Macierz!$K$2:$K$441,A7)
A8: CZĘŚCIOWY | B8: =COUNTIF(Macierz!$K$2:$K$441,A8)
A9: LUKA | B9: =COUNTIF(Macierz!$K$2:$K$441,A9)
A10: POZA ZAKRESEM | B10: =COUNTIF(Macierz!$K$2:$K$441,A10)
A13: Stan implementacji
A14: Wartość | B14: Pozycji
A15: DZIAŁA | B15: =COUNTIF(Macierz!$I$2:$I$441,A15)
A16: CZĘŚCIOWE | B16: =COUNTIF(Macierz!$I$2:$I$441,A16)
A17: FLAGA | B17: =COUNTIF(Macierz!$I$2:$I$441,A17)
A18: ATRAPA | B18: =COUNTIF(Macierz!$I$2:$I$441,A18)
A19: ENDPOINT BEZ UI | B19: =COUNTIF(Macierz!$I$2:$I$441,A19)
A20: BRAK | B20: =COUNTIF(Macierz!$I$2:$I$441,A20)
A21: b.d. | B21: =COUNTIF(Macierz!$I$2:$I$441,A21)
A24: Krytyczność luk
A25: Wartość | B25: Pozycji
A26: BLOKER STARTU | B26: =COUNTIF(Macierz!$L$2:$L$441,A26)
A27: WYSOKA | B27: =COUNTIF(Macierz!$L$2:$L$441,A27)
A28: ŚREDNIA | B28: =COUNTIF(Macierz!$L$2:$L$441,A28)
A29: NISKA | B29: =COUNTIF(Macierz!$L$2:$L$441,A29)
A31: Pokrycie per kategoria
A32: Kategoria | B32: Pozycji | C32: Parytet+Przewaga | D32: Luki | E32: Blokery | F32: Pokrycie
A33: A — Domeny i konta | B33: =COUNTIF(Macierz!$B$2:$B$441,"A") | C33: =COUNTIFS(Macierz!$B$2:$B$441,"A",Macierz!$K$2:$K$441,"PARYTET")+COUNTIFS(Macierz!$B$2:$B$441,"A",Macierz!$K$2:$K$441,"PRZEWAGA") | D33: =COUNTIFS(Macierz!$B$2:$B$441,"A",Macierz!$K$2:$K$441,"LUKA") | E33: =COUNTIFS(Macierz!$B$2:$B$441,"A",Macierz!$L$2:$L$441,"BLOKER STARTU") | F33: =IFERROR(C33/B33,0)
A34: B — Runtime WWW | B34: =COUNTIF(Macierz!$B$2:$B$441,"B") | C34: =COUNTIFS(Macierz!$B$2:$B$441,"B",Macierz!$K$2:$K$441,"PARYTET")+COUNTIFS(Macierz!$B$2:$B$441,"B",Macierz!$K$2:$K$441,"PRZEWAGA") | D34: =COUNTIFS(Macierz!$B$2:$B$441,"B",Macierz!$K$2:$K$441,"LUKA") | E34: =COUNTIFS(Macierz!$B$2:$B$441,"B",Macierz!$L$2:$L$441,"BLOKER STARTU") | F34: =IFERROR(C34/B34,0)
A35: C — Pliki, FTP, SSH, Git | B35: =COUNTIF(Macierz!$B$2:$B$441,"C") | C35: =COUNTIFS(Macierz!$B$2:$B$441,"C",Macierz!$K$2:$K$441,"PARYTET")+COUNTIFS(Macierz!$B$2:$B$441,"C",Macierz!$K$2:$K$441,"PRZEWAGA") | D35: =COUNTIFS(Macierz!$B$2:$B$441,"C",Macierz!$K$2:$K$441,"LUKA") | E35: =COUNTIFS(Macierz!$B$2:$B$441,"C",Macierz!$L$2:$L$441,"BLOKER STARTU") | F35: =IFERROR(C35/B35,0)
A36: D — Bazy danych | B36: =COUNTIF(Macierz!$B$2:$B$441,"D") | C36: =COUNTIFS(Macierz!$B$2:$B$441,"D",Macierz!$K$2:$K$441,"PARYTET")+COUNTIFS(Macierz!$B$2:$B$441,"D",Macierz!$K$2:$K$441,"PRZEWAGA") | D36: =COUNTIFS(Macierz!$B$2:$B$441,"D",Macierz!$K$2:$K$441,"LUKA") | E36: =COUNTIFS(Macierz!$B$2:$B$441,"D",Macierz!$L$2:$L$441,"BLOKER STARTU") | F36: =IFERROR(C36/B36,0)
A37: E — Poczta | B37: =COUNTIF(Macierz!$B$2:$B$441,"E") | C37: =COUNTIFS(Macierz!$B$2:$B$441,"E",Macierz!$K$2:$K$441,"PARYTET")+COUNTIFS(Macierz!$B$2:$B$441,"E",Macierz!$K$2:$K$441,"PRZEWAGA") | D37: =COUNTIFS(Macierz!$B$2:$B$441,"E",Macierz!$K$2:$K$441,"LUKA") | E37: =COUNTIFS(Macierz!$B$2:$B$441,"E",Macierz!$L$2:$L$441,"BLOKER STARTU") | F37: =IFERROR(C37/B37,0)
A38: F — DNS | B38: =COUNTIF(Macierz!$B$2:$B$441,"F") | C38: =COUNTIFS(Macierz!$B$2:$B$441,"F",Macierz!$K$2:$K$441,"PARYTET")+COUNTIFS(Macierz!$B$2:$B$441,"F",Macierz!$K$2:$K$441,"PRZEWAGA") | D38: =COUNTIFS(Macierz!$B$2:$B$441,"F",Macierz!$K$2:$K$441,"LUKA") | E38: =COUNTIFS(Macierz!$B$2:$B$441,"F",Macierz!$L$2:$L$441,"BLOKER STARTU") | F38: =IFERROR(C38/B38,0)
A39: G — SSL i bezpieczeństwo | B39: =COUNTIF(Macierz!$B$2:$B$441,"G") | C39: =COUNTIFS(Macierz!$B$2:$B$441,"G",Macierz!$K$2:$K$441,"PARYTET")+COUNTIFS(Macierz!$B$2:$B$441,"G",Macierz!$K$2:$K$441,"PRZEWAGA") | D39: =COUNTIFS(Macierz!$B$2:$B$441,"G",Macierz!$K$2:$K$441,"LUKA") | E39: =COUNTIFS(Macierz!$B$2:$B$441,"G",Macierz!$L$2:$L$441,"BLOKER STARTU") | F39: =IFERROR(C39/B39,0)
A40: H — Backup i odtwarzanie | B40: =COUNTIF(Macierz!$B$2:$B$441,"H") | C40: =COUNTIFS(Macierz!$B$2:$B$441,"H",Macierz!$K$2:$K$441,"PARYTET")+COUNTIFS(Macierz!$B$2:$B$441,"H",Macierz!$K$2:$K$441,"PRZEWAGA") | D40: =COUNTIFS(Macierz!$B$2:$B$441,"H",Macierz!$K$2:$K$441,"LUKA") | E40: =COUNTIFS(Macierz!$B$2:$B$441,"H",Macierz!$L$2:$L$441,"BLOKER STARTU") | F40: =IFERROR(C40/B40,0)
A41: I — Aplikacje i WordPress | B41: =COUNTIF(Macierz!$B$2:$B$441,"I") | C41: =COUNTIFS(Macierz!$B$2:$B$441,"I",Macierz!$K$2:$K$441,"PARYTET")+COUNTIFS(Macierz!$B$2:$B$441,"I",Macierz!$K$2:$K$441,"PRZEWAGA") | D41: =COUNTIFS(Macierz!$B$2:$B$441,"I",Macierz!$K$2:$K$441,"LUKA") | E41: =COUNTIFS(Macierz!$B$2:$B$441,"I",Macierz!$L$2:$L$441,"BLOKER STARTU") | F41: =IFERROR(C41/B41,0)
A42: J — Wydajność i cache | B42: =COUNTIF(Macierz!$B$2:$B$441,"J") | C42: =COUNTIFS(Macierz!$B$2:$B$441,"J",Macierz!$K$2:$K$441,"PARYTET")+COUNTIFS(Macierz!$B$2:$B$441,"J",Macierz!$K$2:$K$441,"PRZEWAGA") | D42: =COUNTIFS(Macierz!$B$2:$B$441,"J",Macierz!$K$2:$K$441,"LUKA") | E42: =COUNTIFS(Macierz!$B$2:$B$441,"J",Macierz!$L$2:$L$441,"BLOKER STARTU") | F42: =IFERROR(C42/B42,0)
A43: K — Statystyki, logi, limity | B43: =COUNTIF(Macierz!$B$2:$B$441,"K") | C43: =COUNTIFS(Macierz!$B$2:$B$441,"K",Macierz!$K$2:$K$441,"PARYTET")+COUNTIFS(Macierz!$B$2:$B$441,"K",Macierz!$K$2:$K$441,"PRZEWAGA") | D43: =COUNTIFS(Macierz!$B$2:$B$441,"K",Macierz!$K$2:$K$441,"LUKA") | E43: =COUNTIFS(Macierz!$B$2:$B$441,"K",Macierz!$L$2:$L$441,"BLOKER STARTU") | F43: =IFERROR(C43/B43,0)
A44: L — Automatyzacja | B44: =COUNTIF(Macierz!$B$2:$B$441,"L") | C44: =COUNTIFS(Macierz!$B$2:$B$441,"L",Macierz!$K$2:$K$441,"PARYTET")+COUNTIFS(Macierz!$B$2:$B$441,"L",Macierz!$K$2:$K$441,"PRZEWAGA") | D44: =COUNTIFS(Macierz!$B$2:$B$441,"L",Macierz!$K$2:$K$441,"LUKA") | E44: =COUNTIFS(Macierz!$B$2:$B$441,"L",Macierz!$L$2:$L$441,"BLOKER STARTU") | F44: =IFERROR(C44/B44,0)
A45: M — Rozliczenia | B45: =COUNTIF(Macierz!$B$2:$B$441,"M") | C45: =COUNTIFS(Macierz!$B$2:$B$441,"M",Macierz!$K$2:$K$441,"PARYTET")+COUNTIFS(Macierz!$B$2:$B$441,"M",Macierz!$K$2:$K$441,"PRZEWAGA") | D45: =COUNTIFS(Macierz!$B$2:$B$441,"M",Macierz!$K$2:$K$441,"LUKA") | E45: =COUNTIFS(Macierz!$B$2:$B$441,"M",Macierz!$L$2:$L$441,"BLOKER STARTU") | F45: =IFERROR(C45/B45,0)
A46: N — Wsparcie i ops | B46: =COUNTIF(Macierz!$B$2:$B$441,"N") | C46: =COUNTIFS(Macierz!$B$2:$B$441,"N",Macierz!$K$2:$K$441,"PARYTET")+COUNTIFS(Macierz!$B$2:$B$441,"N",Macierz!$K$2:$K$441,"PRZEWAGA") | D46: =COUNTIFS(Macierz!$B$2:$B$441,"N",Macierz!$K$2:$K$441,"LUKA") | E46: =COUNTIFS(Macierz!$B$2:$B$441,"N",Macierz!$L$2:$L$441,"BLOKER STARTU") | F46: =IFERROR(C46/B46,0)
...

Sheet Macierz
A1: ID | B1: Kat | C1: Funkcja | D1: cPanel | E1: Plesk | F1: DirectAdmin | G1: Rynek PL | H1: Nowa fala | I1: Verris — stan | J1: Dowód (plik:linia) | K1: Werdykt | L1: Krytyczność | M1: Nakład | N1: Uwagi
A2: A-01 | B2: A | C2: Dodanie domeny do konta | D2: TAK | E2: TAK | F2: TAK | G2: TAK | H2: TAK | I2: DZIAŁA | J2: services.controller.ts:539 | K2: PARYTET | L2: — | M2: —
A3: A-02 | B3: A | C3: Usunięcie domeny z konta | D3: TAK | E3: TAK | F3: TAK | G3: TAK | H3: TAK | I3: DZIAŁA | J3: services.controller.ts:548 | K3: PARYTET | L3: — | M3: — | N3: 2026-10-08: usunięcie domeny-poddomeny zdejmuje delegację NS/DS w strefie rodzica (60ff05ba) — D3 t1: z10.d3.hvln.pl dodana (NS+DS w d3.hvln.pl) i usunięta (delegacja znika); sieroty test3/4/5, z18b, z09 usunięte z panelu (DS przez dsrecs0 działa). | 2026-10-08 KOD (495019a5): także usunięcie CAŁEGO konta (retencja, operator, RODO, wycofanie provisioningu), którego domena jest poddomeną domeny innego konta na tym węźle (z18b) — domeny konta czytane przed usunięciem, po nim NS/DS zdejmowane w strefie konta-rodzica (najbliższy żywy przodek, ten sam węzeł), audyt HOSTING_DNS_DELEGATION_REMOVED. Testy D2 + integracja. Zostaje: D3 na t1 (konto z domeną-poddomeną d3.hvln.pl → usunięcie przez operatora → NS/DS znikają z d3.hvln.pl). Poza zakresem nadal: rodzic będący domeną dodatkową innego konta.
A4: A-03 | B4: A | C4: Subdomeny — tworzenie | D4: TAK | E4: TAK | F4: TAK | G4: TAK | H4: TAK | I4: DZIAŁA | J4: services.controller.ts:671 | K4: PARYTET | L4: — | M4: —
A5: A-04 | B5: A | C5: Subdomeny — usuwanie | D5: TAK | E5: TAK | F5: TAK | G5: TAK | H5: TAK | I5: DZIAŁA | J5: services.controller.ts:680 | K5: PARYTET | L5: — | M5: —
A6: A-05 | B6: A | C6: Alias / parkowanie domeny (domain pointer) | D6: TAK | E6: TAK | F6: TAK | G6: TAK | H6: TAK | I6: DZIAŁA | J6: services.controller.ts:562 | K6: PARYTET | L6: — | M6: —
A7: A-06 | B7: A | C7: Zmiana document root domeny | D7: TAK | E7: TAK | F7: TAK | G7: CZĘŚĆ | H7: TAK | I7: DZIAŁA | J7: servers/docroot.ts; servers/directadmin.service.ts getHostingDocroot/setHostingDocroot; GET/POST /services/:id/hosting-docroot; client components/hosting/DocrootPanel.tsx; test servers/docroot.spec.ts; D3 t1 28.09: odczyt zawsze błąd — GET CMD_API_CUSTOM_HTTPD zwraca surową treść .cust_httpd → docroot.ts trescCustomHttpd; retest; D3 t1 29.09 (panel klienta, d3.hvln.pl): „Katalog główny strony” → git-test: po ~1 min / serwuje git-test (v.php 8.1.34, readme Hello Dolly, wp-login 404); „Przywróć public_html” → WordPress znów 200 | K7: PARYTET | L7: NISKA | M7: S | N7: DA to potrafi; brak UI | 2026-09-25 ROZPOZNANIE: DirectAdmin nie ma zmiany document root na poziomie użytkownika — robi się to jako administrator w Custom HTTPD Configurations tokenem |?DOCROOT=/home/<user>/domains/<domena>/public_html/<katalog>| (obejmuje http i https), potem przebudowa konfiguracji serwera WWW. Plan: zadanie węzła z białą listą katalogów wewnątrz public_html (np. public/, web/) — typowo pod Laravel/Symfony. Wymaga ustalenia serwera WWW na węźle (J-01: Apache/LiteSpeed/OpenLiteSpeed mają osobne pliki custom), więc budowa razem z D3 na węźle #1. | 2026-09-25 ŹRÓDŁA OFICJALNE: DirectAdmin „Customizing Apache” — token |?DOCROOT=/nowa/ścieżka| w Custom HTTPD (dla samej domeny: |*if !SUB| … |*endif|), plik data/users/<user>/domains/<domena>.cust_httpd, zastosowanie: task.queue action=rewrite&value=httpd albo da build rewrite_confs. LiteSpeed Enterprise na DA czyta tę konfigurację Apache (dokumentacja LiteSpeed), więc na naszym węźle (webserver=litespeed) mechanizm zadziała. Wcześniejsza notka opierała się na źródle nieoficjalnym. | 2026-09-25 ZROBIONE (D2): strona domeny → PHP → „Katalog główny strony”: podkatalog public_html (do 4 poziomów, bez .., katalog musi istnieć). API GET/POST /services/:id/hosting-docroot (reguła FILES_MANAGE, RateLimit 20/h, dziennik HOSTING_DOCROOT_SET). Zapis przez CMD_API_CUSTOM_HTTPD (oficjalny changelog DA 1.26.0: domain + config) jako admin węzła: blok Verris między znacznikami z |*if !SUB| |?DOCROOT=…| |*endif|, wpisy administratora zostają; gdy DA nie odda bieżącego config — odmowa bez zapisu. Bez zadania węzła (DA sam przepisuje httpd.conf). D3 na węźle: format odpowiedzi GET CMD_API_CUSTOM_HTTPD (pole config), uprawnienie klucza admina do tej komendy, czas przebudowy, działanie pod LSWS i HTTPS.
A8: A-07 | B8: A | C8: Przekierowanie domeny (web forwarding) | D8: TAK | E8: TAK | F8: TAK | G8: TAK | H8: TAK | I8: DZIAŁA | J8: WebToolsTab.tsx:143 | K8: PARYTET | L8: — | M8: — | N8: przez .htaccess
A9: A-08 | B9: A | C9: Rejestracja domeny z panelu | D9: NIE | E9: NIE | F9: NIE | G9: TAK | H9: TAK | I9: DZIAŁA | J9: domains.controller.ts:118 | K9: PARYTET | L9: ŚREDNIA | M9: M | N9: Skorygowane: sekcja jest wpięta w panel (domains/actions.ts:165,181,198), backend kompletny. To brak wpisu w ENV, nie brak funkcji — hosting da się sprzedać na domenie klienta. | 2026-09-27 KOD (4cbc9d4): opłacona rejestracja zapisuje domenę na koncie płacącego także wtedy, gdy ktoś wcześniej dopisał tę nazwę do swojego konta bez weryfikacji (wcześniej zostawała u rezerwującego). Test integracyjny. | 2026-10-04: D3 (sandbox OpenProvidera (api.sandbox.openprovider.nl), panel klienta prod, klient d3 czasowo na portfelu) — rejestracja verris-test-d3-2026.com na 1 rok z kreatora: 70,99 zł z portfela, domena „zarejestrowana, wygasa 4.10.2027”, abonent na kliencie (uchwyt OP). Znalezione: domyślne NS ns1/ns2.verris.pl nie istnieją w DNS → 9eb936d4 (NS węzła/platformy). Prawdziwa rejestracja (produkcyjne konto OP) — PB-05 wg decyzji 27.09. | 2026-10-07 KOD + D3: zmiana serwerów nazw zarejestrowanej domeny (panel → Serwery nazw, OpenProvider PUT /v1/domains/{id} name_servers, walidacja 2–8 hostów, audyt DOMAIN_NAMESERVERS_UPDATED) — d91ce97. verris-test-d3-2026.com z 04.10 miała ns1/ns2.verris.pl → ustawione ns3/ns4.verris.pl, rejestrator przyjął.
A10: A-09 | B10: A | C10: Transfer domeny (kod authinfo) | D10: NIE | E10: NIE | F10: NIE | G10: TAK | H10: TAK | I10: CZĘŚCIOWE | J10: POST /domains/:id/registrar/authcode (A-09, tylko właściciel konta, 5/h, audyt DOMAIN_AUTHCODE_REVEALED bez kodu) → OpenProvider GET /v1/domains/{id}/authcode; panel: Domeny → domena → „Transfer i abonent” → Pokaż kod; transfer PRZYCHODZĄCY: formularz z danymi abonenta i oświadczeniem; test domains/abonent-domeny.spec.ts | K10: CZĘŚCIOWY | L10: WYSOKA | M10: M | N10: j.w. | 2026-09-23: kod transferu wychodzącego z panelu. ZNALEZISKO: formularz transferu przychodzącego nie wysyłał oświadczenia o odstąpieniu, a API go wymaga — każdy transfer kończył się błędem 400, bez komunikatu (akcja formularza). Przepisany na formularz z komunikatem błędu. FLAGA do konfiguracji OpenProvider (A-11). | 2026-09-27 KOD: klient zlecał transfer bez zobaczenia kwoty (obciążenie portfela). Nowy POST /domains/registrar/quote-transfer (ta sama ścieżka ceny co transfer()), formularz pokazuje koszt brutto i blokuje „Zleć transfer” bez ceny; pola z etykietami, historia zleceń po polsku (a186d54). D3 przy teście z węzłem. | 2026-09-27 KOD (4cbc9d4): transfer zostawał na zawsze „wysłany do rejestru” — domena nie pojawiała się na koncie po udanym przeniesieniu. Nowe zadanie co godzinę (domains:transfer-sync): stan u rejestratora ACT → domena na koncie płacącego z datą wygaśnięcia, FAI/DEL → zwrot na portfel. Kody stanów OpenProvidera do potwierdzenia przy pierwszym prawdziwym transferze (D3 z węzłem). | 2026-09-27 PRODUKCJA: cena transferu przed zleceniem działa (hvln.pl 0,99 zł brutto, przycisk zablokowany bez ceny, etykiety pól). Poprawka tekstu: transfer .pl nie przedłuża ważności (NASK) — usunięte pole lat i obietnica „przedłużenia o rok” dla .pl. | 2026-10-04: D3 (sandbox OpenProvidera (api.sandbox.openprovider.nl), panel klienta prod, klient d3 czasowo na portfelu) — kod transferu (AuthInfo) z rejestratora: 12 znaków, wyświetlenie w dzienniku; odblokowanie przed transferem działa (A-15). Sam transfer przychodzący — sandbox OP go nie obsługuje; zostaje do produkcyjnego konta OP. | 2026-10-04 DECYZJA WŁAŚCICIELA: prawdziwy transfer przychodzący w PB-05 (produkcyjne konto OP, grudzień). | 2026-10-07 KOD: webhook OpenProvidera (podpis HMAC + klucz, Caddy tylko adresy OP): incomingTransfer* domyka transfer od razu, outgoingTransferCompleted/deletionCompleted = domena odeszła (bez odnowień i przypomnień); codzienne sprawdzenie stanu jako zabezpieczenie — 20c5196. Transfer wychodzący wcześniej nieobsługiwany. Webhook do włączenia: klucze (prod-ustaw-klucze.sh openprovider) + formularz OP. | 2026-10-07 PRODUKCJA: webhook zapisany w panelu OP (sandbox); test OP dotarł do API — 2× REGISTRAR_WEBHOOK w dzienniku (13:16 UTC). Sandbox OP wysyła z 34.91.59.39 (brak w dokumentacji OP, wykryte tcpdumpem) — dopisany do Caddy (503c1c3); odrzucenia logowane z powodem (fe283d0).
A11: A-10 | B11: A | C11: Odnowienie domeny przez klienta | D11: NIE | E11: NIE | F11: NIE | G11: TAK | H11: TAK | I11: DZIAŁA | J11: panel: Domeny → domena → „Odnowienie domeny” (domain-renew-box.tsx: okres → cena z nowego POST domains/:id/registrar/renew-quote → potwierdzenie → POST domains/:id/registrar/renew, obciążenie portfela, zwrot przy błędzie rejestratora); liczba lat walidowana 1–10 (wcześniej body bez walidacji) | K11: PARYTET | L11: ŚREDNIA | M11: S | N11: Skorygowane: brak wywołania potwierdzony, ale obejście istnieje (panel rejestratora). Nie spełnia żadnego z czterech warunków blokera. | 2026-09-23: UI zrobione. Działa po włączeniu rejestratora (A-08/A-11 FLAGA — REGISTRAR_PROVIDER); do tego czasu pole pokazuje się tylko domenom z datą ważności z rejestratora. | 2026-10-04: D3 (sandbox OpenProvidera (api.sandbox.openprovider.nl), panel klienta prod, klient d3 czasowo na portfelu) — „Odnów za 70,99” → „Domena odnowiona”, portfel −70,99 (240,11 po rejestracji i odnowieniu). Błąd: data ważności w panelu została 4.10.2027 (odpowiedź renew bez expiration_date) → 9eb936d4 czyta datę z domeny u rejestratora; retest po wdrożeniu. | 2026-10-04 po c240269: drugie odnowienie w sandboxie — „Ważna do 4.10.2029” (data z rejestru, domainInfo), portfel −70,99 jednorazowo (169,12). Opis w historii „(1 lata/lat)” → „(1 rok)” poprawiony.
A12: A-11 | B12: A | C12: Wyszukiwarka wolnych domen | D12: NIE | E12: NIE | F12: NIE | G12: TAK | H12: TAK | I12: DZIAŁA | J12: domains.controller.ts:54 | K12: PARYTET | L12: WYSOKA | M12: S | N12: DECYZJA WŁAŚCICIELA 2026-09-23: konfiguracja OpenProvider (REGISTRAR_PROVIDER + dane API w .env.prod, wpisuje właściciel) razem z zakupem węzła w sprincie 18; do tego czasu wyszukiwarka za flagą. | 2026-09-25: preflight GO-LIVE blokuje start bez REGISTRAR_PROVIDER (strona oferuje rejestrację domen). Wyszukiwarka na verris.pl prowadzi do /dashboard/domains/buy?domain=… i panel wpisuje nazwę w wyszukiwarkę (wcześniej nazwa przepadała). /domeny: „bez blokad transferu” → blokadę włączasz i zdejmujesz sam (A-15). | 2026-09-27 PRODUKCJA po b0a556f: wyszukiwarka działa — „hvln-test-verris” → 32 wolne warianty z ceną rejestracji i odnowienia (brutto). Przyczyna „wszystko zajęte”: OpenProvider zwraca wyniki w innej kolejności niż w zapytaniu — dopasowanie po nazwie domeny, zapytania po 15 końcówek. Zostaje do pełnego testu z węzłem (decyzja właściciela). | 2026-10-04: D3 (sandbox OpenProvidera (api.sandbox.openprovider.nl), panel klienta prod, klient d3 czasowo na portfelu) — wyszukiwarka: 26 z 32 końcówek z cenami brutto. Po drodze: paczka 15 TLD „wszystko albo nic” gubiła .pl/.com, gdy jedna końcówka wisiała (.online/.shop >40 s w sandboxie) → 36b8bca/9199355/99e38ec (limit 6 s, pojedynczo po błędzie paczki, budżet panelu 40 s); końcówki bez odpowiedzi „Nie sprawdzono” zamiast „Zajęta” → 9eb936d4.
A13: A-12 | B13: A | C13: Cennik rejestracji na 1–10 lat | D13: NIE | E13: NIE | F13: NIE | G13: TAK | H13: TAK | I13: DZIAŁA | J13: POST domains/registrar/quote-periods (domain-registrar.service.ts quotePeriods — ceny brutto dla 1, 2, 3, 5 i 10 lat + cena odnowienia/rok) → kreator zakupu: krok „Okres” z ceną każdego wariantu (domain-purchase-wizard.tsx YEAR_OPTIONS) | K13: PARYTET | L13: ŚREDNIA | M13: S | N13: 2026-09-23 PORZĄDKI: funkcja była zrobiona, wpis „LUKA” był nieaktualny. Działa po włączeniu rejestratora (A-11 FLAGA — REGISTRAR_PROVIDER), tak jak A-10. | 2026-09-27 PRODUKCJA: okresy dla hvln-test-verris.pl — 1 rok 24,99 zł, 2 lata 91,99, 3 lata 192,99, 5 lat 360,99, 10 lat 781,99, odnowienie 83,99 zł/rok (ceny OpenProvider × marża, brutto). Zostaje do pełnego testu z węzłem. | 2026-10-04: D3 (sandbox OpenProvidera (api.sandbox.openprovider.nl), panel klienta prod, klient d3 czasowo na portfelu) — okres 1/2/3/5/10 lat: 70,99 / 140,99 / 211,99 / 352,99 / 705,99 zł brutto dla .com, odnowienie 70,99 zł/rok widoczne przed zakupem; podsumowanie netto 57,72 + VAT 13,27.
A14: A-13 | B14: A | C14: Zmiana danych abonenta domeny | D14: NIE | E14: NIE | F14: NIE | G14: TAK | H14: TAK | I14: DZIAŁA | J14: GET/PUT /domains/:id/registrar/registrant (tylko właściciel konta) → OpenProvider /v1/customers/{handle}; rejestracja i transfer zakładają uchwyt klienta (POST /v1/customers) przed obciążeniem portfela; panel: kreator zakupu, zamówienie hostingu z domeną, transfer, strona domeny; test domains/abonent-domeny.spec.ts | K14: PARYTET | L14: WYSOKA | M14: M | N14: wymóg operatorski przy własnej rejestracji | DECYZJA WŁAŚCICIELA 2026-09-23: abonentem jest KLIENT. ZNALEZISKO: kod rejestrował każdą domenę na uchwyt operatora (OPENPROVIDER_OWNER_HANDLE jako owner) — formalnie domeny należałyby do Verris, sprzecznie z projektem Regulaminu §12 ust. 4 („rejestrowana na dane Klienta”). Nic nie zostało zarejestrowane (rejestrator za flagą), więc zmiana bez migracji. Handle operatora zostaje jako admin/tech/billing. Imię, nazwisko i firmę zmienia tylko cesja (rejestrator nie modyfikuje nazwy uchwytu) — panel odmawia z wyjaśnieniem; adres, telefon, e-mail, NIP — z panelu. PRZY OKAZJI: /v1beta → /v1 (OpenProvider wyłącza v1beta 2027-06-30). D3 przy pierwszej domenie po konfiguracji OpenProvider. | 2026-10-04: D3 (sandbox OpenProvidera (api.sandbox.openprovider.nl), panel klienta prod, klient d3 czasowo na portfelu) — „Dane abonenta”: odczyt z rejestratora, zmiana miasta/kodu (Warszawa 00-001 → Kraków 30-001) „zapisane u rejestratora”, po przeładowaniu odczyt z OP pokazuje nowe dane; imię/nazwisko/firma tylko przez cesję (zgłoszenie).
A15: A-14 | B15: A | C15: Ukrycie danych WHOIS / domain privacy | D15: NIE | E15: NIE | F15: NIE | G15: b.d. | H15: TAK | I15: DZIAŁA | J15: domain-registrar.service.ts setWhoisPrivacy (OpenProvider PUT /v1/domains/{id} is_private_whois_enabled); Domain.whoisPrivacy; zamówienie WHOIS_PRIVACY; ustawienie domain.whoisPrivacyYearlyPrice (puste = ukryte); migracja 20261005160000_ukrycie_whois | K15: PARYTET | L15: NISKA | M15: S | N15: DECYZJA WŁAŚCICIELA 2026-09-24: po starcie — u OpenProvider ukrycie WHOIS to usługa płatna per domena, a dla osób fizycznych z .pl rejestr i tak nie publikuje danych; wracamy przy sprzedaży domen, gdy znane będą koszty. | 2026-10-05 KOD (decyzja właściciela: budujemy teraz; członkostwo OP Basic „S” — usługa płatna): dodatek płatny, cena brutto za rok w Ustawieniach platformy (puste = niedostępne), opłata za rozpoczęte lata do wygaśnięcia + dopłata przy odnowieniu, odmowa rejestru → zwrot (bc35db54). Zostaje: cena od właściciela, test w sandboxie OP (model opłat, kod błędu .pl). | 2026-10-05 KOREKTA STANU: kod jest (c2bd935), wpis zostawał „BRAK/LUKA” — teraz FLAGA (cena pusta = funkcja ukryta) · CZĘŚCIOWY do ceny i testu w sandboxie OP. | 2026-10-06 D3 SANDBOX: włączenie ukrycia dla verris-test-d3-2026.com (29,97 K = 3 lata do końca ważności) — OpenProvider „Wpp contract is not signed”; zwrot zadziałał; komunikat klienta poprawiony (0827480). Zostaje: akceptacja umowy WPP w panelu OpenProvidera (właściciel), ponowny test. | 2026-10-07 D3 SANDBOX po podpisaniu umowy WPP (sandbox + produkcja): włączenie dla verris-test-d3-2026.com — 29,97 K z portfela, „Dane w WHOIS ukryte”; wyłączenie bez opłaty działa. Zamknięte 2026-10-07. Do decyzji: ponowne włączenie w tym samym okresie pobiera opłatę jeszcze raz. | 2026-10-07 DECYZJA WŁAŚCICIELA: ukrycie danych bezpłatne (WPP w członkostwie OpenProvidera), cena dalej ustawiana w adminie: 0 = bezpłatnie, puste = niedostępne (3bc7107). D3: cena 0 w adminie, włączenie na verris-test-d3-2026.com — audyt priceAmount 0.00, bez zamówienia i bez obciążenia portfela. Kwestia ponownej opłaty w tym samym okresie nieaktualna.
A16: A-15 | B16: A | C16: Blokada transferu domeny (transfer lock) | D16: NIE | E16: NIE | F16: NIE | G16: b.d. | H16: TAK | I16: DZIAŁA | J16: POST /domains/:id/registrar/lock → OpenProvider PUT /v1/domains/{id} {is_locked}; stan w Domain.transferLock + audyt DOMAIN_TRANSFER_LOCKED/UNLOCKED; panel: strona domeny „Transfer i abonent”; test domains/abonent-domeny.spec.ts | K16: PARYTET | L16: ŚREDNIA | M16: S | N16: 2026-09-23: przełącznik blokady w panelu. FLAGA do konfiguracji OpenProvider (A-11). | 2026-10-04: D3 (sandbox OpenProvidera (api.sandbox.openprovider.nl), panel klienta prod, klient d3 czasowo na portfelu) — blokada transferu: domyślnie włączona, „Odblokuj” → wyłączona (po przeładowaniu z rejestratora nadal wyłączona), „Zablokuj” → włączona.
A17: A-16 | B17: A | C17: Weryfikacja własności domeny | D17: NIE | E17: NIE | F17: NIE | G17: b.d. | H17: b.d. | I17: DZIAŁA | J17: domains.service.ts verifyDomain — ACTIVE tylko po rekordzie TXT _verris-challenge.<domena> = verris-verify=<HMAC(id,właściciel)>; create zwalnia cudzą niezweryfikowaną rezerwację po 7 dniach; klient: domains/[id] — instrukcja TXT z kopiowaniem; testy D2 domains.service.spec.ts | K17: PARYTET | L17: WYSOKA | M17: M | N17: OBALONE w passie adwersaryjnym: to checklist konfiguracji, nie dowód własności. Brak wyzwania TXT i tokenu — dowolny użytkownik może dodać cudzą domenę i doprowadzić ją do statusu ACTIVE. | 2026-09-23: domena przechodzi w ACTIVE dopiero po opublikowaniu rekordu TXT (wartość różna dla każdego właściciela, liczona HMAC — bez migracji). Checklist A/NS/TLS zostaje jako asystent konfiguracji, nie dowód. Anty-squatting: niezweryfikowana cudza rezerwacja po 7 dniach nie blokuje nazwy. Domeny kupione przez rejestratora są ACTIVE z zakupu. D3 na pierwszej domenie klienta.
A18: A-17 | B18: A | C18: Rejestracja konta klienta (self-service) | D18: NIE | E18: NIE | F18: NIE | G18: TAK | H18: TAK | I18: DZIAŁA | J18: auth.controller.ts:67 | K18: PARYTET | L18: — | M18: — | N18: captcha + weryfikacja e-mail
A19: A-18 | B19: A | C19: Logowanie hasłem | D19: TAK | E19: TAK | F19: TAK | G19: TAK | H19: TAK | I19: DZIAŁA | J19: auth.controller.ts:77 | K19: PARYTET | L19: — | M19: —
A20: A-19 | B20: A | C20: Zamówienie usługi z panelu | D20: NIE | E20: NIE | F20: NIE | G20: TAK | H20: TAK | I20: DZIAŁA | J20: subscriptions.controller.ts:97 | K20: PARYTET | L20: — | M20: —
A21: A-20 | B21: A | C21: Okres próbny / trial | D21: NIE | E21: NIE | F21: NIE | G21: CZĘŚĆ | H21: TAK | I21: DZIAŁA | J21: subscriptions.controller.ts:53 | K21: PARYTET | L21: — | M21: — | N21: 3 z 5 hostingów PL ma trial lub money-back | 2026-10-06: trial omijał blokadę PB-28 (rozliczani poza Verris) — 645a250 (test trial.billing-outside.spec.ts).
A22: A-21 | B22: A | C22: Anulowanie usługi przez klienta | D22: NIE | E22: NIE | F22: NIE | G22: TAK | H22: TAK | I22: DZIAŁA | J22: subscriptions.controller.ts:103; D3 t1 (d3.hvln.pl) 29.09 00:38: rezygnacja „od razu” z mailtest-verris.pl w panelu klienta → status Anulowana, konto DA zawieszone | K22: PARYTET | L22: — | M22: —
A23: A-22 | B23: A | C23: Zmiana planu (upgrade/downgrade) z proratą | D23: NIE | E23: NIE | F23: NIE | G23: CZĘŚĆ | H23: TAK | I23: DZIAŁA | J23: subscriptions.controller.ts:146,161 | K23: PRZEWAGA | L23: — | M23: — | N23: prorata cross-interval MONTH↔YEAR; test D1 | 2026-09-27 ZNALEZISKO (naprawione c0991f1): zmiana okresu rozliczeniowego liczyła koszt jak resztę starego okresu, a zaczynała nowy pełny okres — miesiąc→rok w połowie miesiąca = rok gratis + ~6 zł zwrotu; rok→miesiąc = dopłata ~136 zł zamiast zwrotu. Teraz pełna cena nowego okresu minus niewykorzystana część starego (Regulamin: zmiana okresu rozpoczyna nowy okres). Równoległe zmiany planu zajmują usługę warunkowo (drugie żądanie 409). Test integracyjny zmiana-planu.int-spec.ts. DO SPRAWDZENIA NA PRODUKCJI: czy ktoś zmieniał okres z portfela (zdarzenia PLAN_CHANGED z intervalChange=true). | 2026-09-27 PRODUKCJA: sprawdzone w dzienniku — 0 zmian okresu rozliczeniowego (PLAN_CHANGED z intervalChange=true), błąd nie został wykorzystany; bez korekt wstecz.
A24: A-23 | B24: A | C24: Dane dostępowe usługi (IP/FTP/NS/limity) | D24: TAK | E24: TAK | F24: TAK | G24: TAK | H24: TAK | I24: DZIAŁA | J24: services.controller.ts:355 | K24: PARYTET | L24: — | M24: —
A25: A-24 | B25: A | C25: Zakładanie konta klienta przez operatora | D25: TAK | E25: TAK | F25: TAK | G25: TAK | H25: TAK | I25: DZIAŁA | J25: POST /admin/users (users.admin.controller.ts createCustomer, CUSTOMERS_MANAGE) → UsersAdminService.createCustomerByOperator; admin: Klienci → „Nowy klient” (create-customer-button.tsx); testy D2 users.admin.create-customer.spec.ts + users.admin.controller.spec.ts | K25: PARYTET | L25: WYSOKA | M25: M | N25: Skorygowane: konta powstają też przez rejestrację (auth.service.ts:132) — operator może zarejestrować za klienta i wejść przez impersonację (users.admin.controller.ts:248). Pierwsze konto da się sprzedać. | 2026-09-23: operator zakłada konto bez znajomości hasła — klient dostaje link „ustaw hasło” (72 h, token PASSWORD_RESET), ustawienie hasła potwierdza e-mail. Zgód nie składamy w imieniu klienta: regulamin akceptuje sam przy pierwszym logowaniu. Audyt ADMIN_CUSTOMER_CREATED_BY_OPERATOR. D3 przy pierwszym koncie z telefonu.
A26: A-25 | B26: A | C26: Ręczne zawieszenie usługi przez operatora | D26: TAK | E26: TAK | F26: TAK | G26: TAK | H26: TAK | I26: DZIAŁA | J26: 2026-09-23 D1: admin-panel subscriptions/[id]/suspend-form.tsx + suspend-actions.ts → POST /admin/subscriptions/:id/suspend (powód, notatka, potwierdzenie); D3 t1 (d3.hvln.pl) 29.09 01:1x: zawieszenie z panelu admina (Decyzja operatora + notatka) → strona pokazuje stronę zawieszenia DA, sesja DA klienta wylogowana. Uwaga: strona zawieszenia to domyślna, angielska strona DA (bez marki Verris) | K26: PARYTET | L26: — | M26: S | N26: Skorygowane: endpoint działa i jest osiągalny (curl + DirectAdmin), auto-suspend za brak płatności działa. Brakuje UI, nie możliwości zatrzymania szkody. | UI zrobione. OTWARTE do D3 (PB-21, serwer testowy): zawieszenie konta w DirectAdminie na żywym węźle.
A27: A-26 | B27: A | C27: Ręczne odwieszenie usługi przez operatora | D27: TAK | E27: TAK | F27: TAK | G27: TAK | H27: TAK | I27: DZIAŁA | J27: 2026-09-23 D1: ten sam formularz — odwieszenie z opcją obciążenia za odnowienie (chargeRenewal); D3 t1 (d3.hvln.pl) 29.09: odwieszenie bez obciążenia → WordPress wraca po kilku sekundach | K27: PARYTET | L27: — | M27: S | N27: Skorygowane: jak A-25, endpoint subscriptions.admin.controller.ts:210 działa z chargeRenewal. | UI zrobione. OTWARTE do D3 (PB-21): odwieszenie konta w DA na żywym węźle.
A28: A-27 | B28: A | C28: Pakiety / plany zasobów po stronie operatora | D28: TAK | E28: TAK | F28: TAK | G28: TAK | H28: TAK | I28: DZIAŁA | J28: plans.admin.controller.ts:45 | K28: PARYTET | L28: — | M28: —
A29: A-28 | B29: A | C29: Impersonacja klienta przez operatora | D29: TAK | E29: TAK | F29: TAK | G29: b.d. | H29: b.d. | I29: DZIAŁA | J29: users.admin.controller.ts:248; common/auth/przekazanie-sesji.ts | K29: PARYTET | L29: — | M29: — | N29: z banerem u klienta | 2026-09-25 (impersonacja „jako klient”): (1) /impersonate przyjmował dowolny token — link ze zwykłym tokenem napastnika logował ofiarę na jego konto (login CSRF); teraz tylko token z claimem impersonatedBy (podpis sprawdza API). (2) returnTo „//host” przechodziło jako ścieżka → przekierowanie na obcą domenę; teraz tylko ścieżki panelu. (3) token impersonacji nie niósł wersji sesji, więc u klientów po „wyloguj wszędzie”/resecie hasła impersonacja od razu kończyła się 401; teraz tv = tokenVersion klienta. (4) działania w impersonacji trafiają do dziennika z impersonatedBy (G-18). Test apps/client-panel/src/app/impersonate/route.spec.ts. | 2026-09-25 (przegląd adwersaryjny paneli): token impersonacji nie idzie już w URL — API zwraca jednorazowy kod (60 s, jednorazowy), panel klienta wymienia go serwer-serwer na POST /auth/handoff; zły kod nie wylogowuje klienta; returnTo tylko ta sama origin (zamknięty open redirect „/\t/evil”). Dowód: common/auth/przekazanie-sesji.ts + spec, client-panel impersonate/route.spec.ts. | 2026-10-10: przycisk „Zaloguj jako klient” w panelu obsługi tylko z CUSTOMERS_VIEW + CUSTOMERS_IMPERSONATE (staff-panel lib/staff-access.ts:31-35, test zaloguj-jako-klient.spec.tsx); passkey klienta zablokowany w sesji impersonacji (33d775dc, audyt bezpieczeństwa 09.10 A07).
A30: B-01 | B30: B | C30: Zmiana wersji PHP dla całego konta | D30: TAK | E30: TAK | F30: TAK | G30: TAK | H30: TAK | I30: DZIAŁA | J30: services.controller.ts:125; D3 t1 28.09: FAIL — selektor bez alt-php (profil nie instalował els-php-release/alt-phpXX na CL10), panel pokazywał wersję mimo błędu → profil + PHP_APPLY cofa wersję (int: php-odrzucona-zmiana.int-spec.ts); retest po profilu; D3 t1 (d3.hvln.pl) 28.09 23:31: PHP 8.2 dla konta z panelu → strona zwraca 8.2.33 na LiteSpeed (PHP_APPLY zakończone); odrzucona zmiana cofa wersję (int) | K30: PARYTET | L30: — | M30: S | N30: KOREKTA: pozycja miała stan DZIAŁA na podstawie kodu i kolejki PHP_APPLY. Odkryte 2026-08-21 przy przeglądzie Dockerfile.api: loadery skryptów w API czytają plik z dysku i rzucają wyjątkiem, gdy go nie ma, a obraz produkcyjny kopiował tylko 7 z 10 potrzebnych skryptów. Endpoint /agent/tasks/php-apply/script zwracał 500, więc agent nie miał czego uruchomić — zadanie PHP_APPLY nie mogło się wykonać na produkcji ani razu. Naprawione (COPY + test apps/api/src/test/dockerfile-scripts.spec.ts), ale do czasu potwierdzenia na produkcji stan to CZĘŚCIOWE: kod i testy były zielone przez cały czas, więc D1 i D2 nic tu nie dowodzą — potrzebny D3. | 2026-08-21 21:57: przyczyna wdrożeniowa USUNIĘTA — node-php-apply.sh jest już w obrazie (potwierdzone na serwerze, X-12 D3). Pozycja zostaje CZĘŚCIOWE, bo jej własny dowód wymaga wykonania zadania PHP_APPLY na żywym węźle, a węzła jeszcze nie ma. Do przejścia z części B checklisty D3. | WYCENA 2026-09-19: krytycznosc i naklad uzupelnione przy wznowieniu. Pozycje przepisane 2026-08-28 w ramach X-49 zostaly bez wyceny, przez co nie liczyly sie do budzetu godzin i nie stały w zadnym sprincie. Podstawa wyceny: Zmiana wersji PHP dla calego konta — per domena juz dziala (B-02, S), to ten sam mechanizm o poziom wyzej. | 2026-09-22: przeniesione do sprintu 18 — kod i obraz sa gotowe, zostal wylacznie dowod D3 (PHP_APPLY na zywym wezle).
A31: B-02 | B31: B | C31: Zmiana wersji PHP per domena | D31: TAK | E31: TAK | F31: TAK | G31: TAK | H31: TAK | I31: DZIAŁA | J31: services.controller.ts — GET/POST /services/:id/hosting-domain-php; directadmin.service.ts:2058; D3 t1 28.09: slot DA php1_select wskazywał nieistniejące php2_release i wyłączał selektor CL → teraz alt-php w bloku Verris .htaccess domeny: htaccess.service.ts phpDomeny/phpDomenyStatus, node-htaccess.sh „zachowaj”; retest po alt-php; 29.09 profil: [OK] handlery alt-php 83/82/81/80/74 w LiteSpeed — retest PHP domeny do zrobienia; D3 t1 29.09 rano: PHP 8.1 per domena z panelu cofany przez sondę node-htaccess (LiteSpeed potrzebuje chwili po zmianie .htaccess; ręcznie 7.4/8.1/8.2 działają) — poprawka 3273ffa (6 prób, https) czeka na push; D3 t1 (d3.hvln.pl) 29.09 po wdrożeniu (panel klienta): PHP 8.1 dla domeny z panelu → „używana teraz”, strona odpowiada PHP/8.1.34; powrót „Jak konto” działa (3273ffa) | K31: PARYTET | L31: — | M31: S | N31: Decyzja produktowa: ustawienie per domena wygrywa nad ustawieniem konta, a UI musi to pokazywać — php-client.tsx wypisuje domeny z własną wersją PHP przy karcie konta. Zamknięte 2026-08-21 (commit 6f2833d). Strażnik: apps/api/src/test/ui-routes-coverage.spec.ts porównuje wszystkie wywołania apiFetch z panelu ze wszystkimi trasami API — nawrót tej klasy błędu zapala test.
A32: B-03 | B32: B | C32: Zmiana wersji PHP per katalog | D32: TAK | E32: TAK | F32: TAK | G32: CZĘŚĆ | H32: NIE | I32: DZIAŁA | J32: ops/scripts/node-htaccess.sh (HT_DIR, HT_PHP); htaccess.service.ts phpKatalogu; services.controller.ts :id/hosting-htaccess/php-dir; client-panel PhpKatalogPanel (widok strony → PHP i serwer); test htaccess.service.spec.ts; D3 t1 29.09 (panel klienta, d3.hvln.pl): „PHP w podkatalogu” git-test → PHP 8.1: /git-test/v.php zwraca 8.1.34, reszta strony dalej 8.2.33 | K32: PARYTET | L32: NISKA | M32: M | N32: | ZROBIONE W KODZIE 2026-09-25: wersja PHP podkatalogu wg dokumentacji LiteSpeed (DirectAdmin → PHP): <IfModule LiteSpeed> AddHandler application/x-httpd-alt-phpXY .php w bloku Verris pliku .htaccess tego katalogu (CloudLinux alt-php). Katalog sprawdzany jako klient po rozwinięciu dowiązań (dowiązanie poza stronę → odmowa), wersja musi być zainstalowana (/opt/alt/phpXY), po zapisie kontrola katalogu i powrót poprzedniego pliku przy 5xx. Sprawdzone lokalnie (zapis, odczyt, wyczyszczenie, 5 odmów). D3 w wezel.csv.
A33: B-04 | B33: B | C33: Włączanie/wyłączanie rozszerzeń PHP | D33: TAK | E33: TAK | F33: TAK | G33: CZĘŚĆ | H33: TAK | I33: DZIAŁA | J33: ops/scripts/node-php-info.sh (selektor); ops/scripts/node-php-apply.sh (PHP_EXT_ENABLE/DISABLE); subscriptions/php.service.ts setExtensionsForSubscription; POST /services/:id/hosting-php/extensions; client PhpInfoPanel.tsx; testy php.service.spec.ts, php-info.service.spec.ts; D3 t1 29.09 (panel klienta, d3.hvln.pl): włączenie opcache i redis dla PHP 8.2 z panelu → ponowny odczyt: 59 rozszerzeń, opcache.enable = włączone, redis załadowany | K33: PARYTET | L33: ŚREDNIA | M33: M | N33: 2026-09-24: podgląd włączonych rozszerzeń jest (B-06). Przełączanie z panelu wymaga selektora PHP na węźle (CloudLinux/alt-php) — do decyzji przy konfiguracji węzła w sprincie 21; do tego czasu włączamy na prośbę w zgłoszeniu (tekst w panelu). | 2026-09-25 ZROBIONE (D2) wg oficjalnej dokumentacji CloudLinux (selectorctl): odczyt PHP_INFO dokłada --user-current i --list-user-extensions --all (+ włączone, - wyłączone, ~ wbudowane); panel strony → PHP → „Aktualna konfiguracja PHP” ma przełączniki rozszerzeń (wbudowane zablokowane) i „Zastosuj zmiany” → zadanie PHP_APPLY z --enable/--disable-user-extensions dla bieżącej wersji. Przy okazji PHP_APPLY poprawione na oficjalne --set-user-current (było --set-current-version, którego nie ma w dokumentacji) i usunięty „zapasowy” wpis do task.queue DA, który zgłaszał sukces bez zmiany — bez selectorctl zadanie kończy się czytelnym błędem. D3 na węźle: selectorctl dostępny, konto na alt-php (nie native), przełączenie intl/imagick widoczne w ponownym odczycie.
A34: B-05 | B34: B | C34: Edycja dyrektyw php.ini z panelu | D34: TAK | E34: TAK | F34: TAK | G34: TAK | H34: TAK | I34: DZIAŁA | J34: servers/php-ini.ts (lista dozwolonych dyrektyw, zakresy), directadmin.service.ts getHostingPhpIni/setHostingPhpIni (blok panelu w .user.ini domeny), services.controller.ts :id/hosting-php-ini, client-panel components/hosting/PhpIniForm.tsx (widok strony → PHP); testy php-ini.spec.ts + directadmin.domeny.spec.ts; D3 t1 (d3.hvln.pl) 29.09 po wdrożeniu (panel klienta): memory_limit 256M z panelu → blok Verris w .user.ini domeny; D3 t1 29.09: memory_limit 256M z .user.ini nie działał na LiteSpeed (LSAPI bez LSPHP_ENABLE_USER_INI); php_value w .htaccess działa (test 300M) — 98e6f24 zapisuje oba | K34: PARYTET | L34: — | M34: M | N34: 2026-09-24: KOD (D2) — ustawienia PHP per domena z panelu: memory_limit, upload_max_filesize, post_max_size, max_execution_time, max_input_time, max_input_vars, display_errors, date.timezone. Zapis w bloku zarządzanym .user.ini; wpisy klienta poza blokiem zostają. OTWARTE do D3 (sprint 18, węzeł): czy PHP (FPM/LSAPI) czyta .user.ini z docroot i po ilu minutach. | 4 z 5 hostingów PL to ma | 2026-09-24 SKALA DOWODU (decyzja PM): funkcja bez pieniędzy, danych klienta i dostępu — D2 (test w CI) wystarcza do „zrobione”, więc werdykt PARYTET. Stan zostaje CZĘŚCIOWE do testu na węźle (audyt/dane/wezel.csv). | 2026-09-29 D3 t1: memory_limit 512M ustawiony w panelu działa na LiteSpeed (odczyt przez serwer WWW) — blok php_value w .htaccess (98e6f24).
A35: B-06 | B35: B | C35: Podgląd aktualnej konfiguracji PHP (phpinfo) | D35: TAK | E35: TAK | F35: TAK | G35: CZĘŚĆ | H35: TAK | I35: DZIAŁA | J35: ops/scripts/node-php-info.sh; subscriptions/php-info.service.ts; PhpInfoPanel.tsx (strona → PHP i serwer); D3 t1 28.09: FAIL — odczyt przez 127.0.0.1 trafiał w stronę domyślną (vhosty DA na IP konta) → ip= z user.conf; retest; D3 t1 (d3.hvln.pl) 28.09 23:39: podgląd konfiguracji PHP zakończony po poprawce ip= z user.conf | K35: PARYTET | L35: — | M35: S | N35: 2026-09-24: KOD (D2) + skrypt sprawdzony lokalnie na serwerze PHP — konfiguracja tak, jak widzi ją serwer WWW strony (nie PHP z konsoli): wersja, SAPI, 22 dyrektywy i lista rozszerzeń. Plik o losowej nazwie w katalogu strony, odczyt przez 127.0.0.1 z nagłówkiem Host (HTTP, potem HTTPS), usuwany zawsze — także przy błędzie. Bez pełnego phpinfo() (zmienne środowiska, ścieżki). OTWARTE do D3 (sprint 21). | 2026-09-24 SKALA DOWODU (decyzja PM): funkcja bez pieniędzy, danych klienta i dostępu — D2 (test w CI) wystarcza do „zrobione”, więc werdykt PARYTET. Stan zostaje CZĘŚCIOWE do testu na węźle (audyt/dane/wezel.csv).
A36: B-07 | B36: B | C36: Wybór handlera PHP (LSAPI/FPM/CGI) | D36: TAK | E36: TAK | F36: TAK | G36: NIE | H36: NIE | I36: BRAK | J36: — | K36: POZA ZAKRESEM | L36: NISKA | M36: — | N36: decyzja operatorska, nie klienta
A37: B-08 | B37: B | C37: Aplikacje Node.js | D37: TAK | E37: TAK | F37: CZĘŚĆ | G37: NIE | H37: TAK | I37: DZIAŁA | J37: ops/scripts/node-app-selector.sh (zadanie APP_SELECTOR); subscriptions/app-selector.service.ts; services.controller.ts :id/hosting-apps; client-panel components/hosting/AplikacjeSelektorPanel.tsx (zakładka Aplikacje); node-hosting-profile.sh (alt-nodejs/alt-python + selektory włączone); testy test/aplikacje-selektor.spec.ts, app-selector.service.spec.ts | K37: PARYTET | L37: NISKA | M37: L | N37: żaden z 5 hostingów PL tego nie ma | 2026-09-25 KOD (D2): CloudLinux Selector wg oficjalnej dokumentacji (docs.cloudlinux.com → Command-line tools → Node.js/Python Selector; instalacja DirectAdmin: alt-nodejs/alt-python, lvemanager lve-utils alt-python-virtualenv alt-mod-passenger, --selector-status enabled). Zakładka Aplikacje → „Aplikacje Node.js i Python”: utwórz (język, wersja z serwera, domena + ścieżka, katalog poza public_html, plik startowy, obiekt WSGI, zmienne środowiskowe), edytuj (wersja, plik startowy, zmienne), uruchom/zatrzymaj/restart, zależności (npm install / pip -r requirements.txt), usuń. Wartości klienta w osobnych argumentach selektora (bez powłoki), zmienne nie trafiają do dziennika zdarzeń. Subkonto: FILES_MANAGE. D3 w wezel.csv. | 2026-09-30 D3 t1: 30.09: „Utwórz aplikację” (Node.js, d3.hvln.pl/nodetest) → „zmienne środowiskowe są niepoprawne” dla każdej aplikacji: agent ucinał końcowe „=” base64 (IFS='=' read) — to samo psuło klucze SSH → 4569ee5. Retest po wdrożeniu. | 2026-10-01 D3 t1: 01.10 po 4569ee5: Node.js d3.hvln.pl/nodetest — tworzenie, „Zależności” (Express 5.2.1 z package.json), zmienne środowiskowe, zatrzymaj/uruchom, restart, usuń działają. „Edytuj” → surowy błąd selektora (pełna wersja zamiast głównej) → d284195, retest. | 01.10 na t1 z panelu: utwórz, zależności, zmienne, zatrzymaj/uruchom, restart, edytuj, usuń — Node (Express) i Python (Flask) działają.
A38: B-09 | B38: B | C38: Aplikacje Python | D38: TAK | E38: TAK | F38: CZĘŚĆ | G38: CZĘŚĆ | H38: CZĘŚĆ | I38: DZIAŁA | J38: ops/scripts/node-app-selector.sh (zadanie APP_SELECTOR); subscriptions/app-selector.service.ts; services.controller.ts :id/hosting-apps; client-panel components/hosting/AplikacjeSelektorPanel.tsx (zakładka Aplikacje); node-hosting-profile.sh (alt-nodejs/alt-python + selektory włączone); testy test/aplikacje-selektor.spec.ts, app-selector.service.spec.ts | K38: PARYTET | L38: NISKA | M38: L | N38: 2026-09-25 KOD (D2): CloudLinux Selector wg oficjalnej dokumentacji (docs.cloudlinux.com → Command-line tools → Node.js/Python Selector; instalacja DirectAdmin: alt-nodejs/alt-python, lvemanager lve-utils alt-python-virtualenv alt-mod-passenger, --selector-status enabled). Zakładka Aplikacje → „Aplikacje Node.js i Python”: utwórz (język, wersja z serwera, domena + ścieżka, katalog poza public_html, plik startowy, obiekt WSGI, zmienne środowiskowe), edytuj (wersja, plik startowy, zmienne), uruchom/zatrzymaj/restart, zależności (npm install / pip -r requirements.txt), usuń. Wartości klienta w osobnych argumentach selektora (bez powłoki), zmienne nie trafiają do dziennika zdarzeń. Subkonto: FILES_MANAGE. D3 w wezel.csv. | 2026-09-30 D3 t1: 30.09: ten sam błąd co B-08 (base64 zmiennych bez końcowego „=”) → 4569ee5. Retest po wdrożeniu. | 2026-10-01 D3 t1: 01.10: Python dawał 503 (brak lswsgi: 3552440 profil, 972a40e bez wersji bez lswsgi — 3.14), potem 500 (passenger_wsgi.py jako plik startowy ładował sam siebie → 39df336). Z app.py: d3.hvln.pl/flask — Flask 3.1.3 z requirements.txt przez „Zależności”, restart działają. Retest „Edytuj” po d284195. | 01.10 na t1 z panelu: utwórz, zależności, zmienne, zatrzymaj/uruchom, restart, edytuj, usuń — Node (Express) i Python (Flask) działają. | 2026-10-03: profil instaluje brakujący alt-pythonXY-wsgi-lsapi (skrypt LSWS ma listę wersji do 3.13); t1: python314 dostał lswsgi, profil „[OK] Python przez LiteSpeed (lswsgi)”, WARN=0. Bez pakietu wersja jest wyłączana w selektorze (cloudlinux-selector disable-version).
A39: B-10 | B39: B | C39: Aplikacje Ruby | D39: TAK | E39: TAK | F39: NIE | G39: NIE | H39: NIE | I39: BRAK | J39: — | K39: POZA ZAKRESEM | L39: NISKA | M39: — | N39: rynek PL tego nie oczekuje
A40: B-11 | B40: B | C40: Wymuszenie HTTPS | D40: TAK | E40: TAK | F40: TAK | G40: TAK | H40: TAK | I40: DZIAŁA | J40: WebToolsTab.tsx:120 | K40: PARYTET | L40: — | M40: —
...
