Workbook

Sheet Podsumowanie
A1: Verris — backlog do startu
A2: 23 sprintów · 65 h netto na sprint · wygenerowane 2026-10-11 z audyt/dane/
A4: Kluczowe liczby
A6: Zadań w planie | B6: =COUNTA('Backlog do startu'!$A$2:$A$138)
A7: Godzin w planie | B7: =SUM('Backlog do startu'!$F$2:$F$138)
A8: Pojemność | B8: 1495
A9: Zapas | B9: =B7-B6
A10: Blokerów | B10: =COUNTIF('Backlog do startu'!$E$2:$E$138,"BLOKER STARTU")+COUNTIF('Backlog do startu'!$E$2:$E$138,"BLOKER BIZNESOWY")
A11: Zadań zrobionych | B11: =COUNTIF('Backlog do startu'!$P$2:$P$138,"zrobione")
A12: Godzin zrobionych | B12: =SUMIF('Backlog do startu'!$P$2:$P$138,"zrobione",'Backlog do startu'!$F$2:$F$138)
A13: Postęp | B13: =IFERROR(B12/B6,0)
A15: Praca poza planem sprintów
A16: Pozycji w roadmapie po starcie | B16: 18
A17: Godzin | B17: 444
A18: Sprintów po tyle godzin | B18: 6.8
A19: Pozycji poza zakresem | B19: 21
A21: Jak używać tego pliku
A22: • Edytuje się WYŁĄCZNIE kolumnę Status w arkuszu „Backlog do startu”: do zrobienia / w toku / zrobione.
A23: • Liczby powyżej i obciążenie sprintów przeliczają się same.
A24: • „Zrobione” = spełniona definicja ukończenia z kolumny N, nie „kod napisany”.
A25: • Nic poniżej D2 (test w CI) nie jest zrobione. Pieniądze, dane i dostęp → D3. Backupy i DR → D4.
A26: • Reszta pliku jest generowana z audyt/dane/ — zmiany rób tam i uruchom audyt/generate.py.

Sheet Backlog do startu
A1: ID | B1: Zadanie | C1: Typ | D1: Kategoria | E1: Priorytet | F1: h | G1: Sprint | H1: Faza | I1: Od | J1: Do | K1: Stan w kodzie | L1: Dowód (plik:linia) | M1: Zależy od | N1: Definicja ukończenia | O1: Kontekst | P1: Status
A2: X-01 | B2: CI uruchamiające testy | C2: audyt | D2: X — Infrastruktura jakości | E2: — | F2: 6 | G2: 1 | H2: Faza 0 — Zatrzymać krwawienie | I2: 2026-08-31 | J2: 2026-09-04 | K2: DZIAŁA | L2: .github/workflows/ci.yml — typecheck, testy API, build, smoke migracji Prisma, gitleaks, pnpm audit, Trivy, dependabot | M2: — | N2: Funkcja dostępna z panelu klienta bez wychodzenia do DirectAdmina; test uruchamiany w CI. | O2: SPROSTOWANIE: pierwotny zapis „katalog .github NIE ISTNIEJE" był mój błąd — .github wypadło z archiwum, na którym pracowałem, i wziąłem to za brak w repo. CI istniało i było sensowne, ale chodziło wyłącznie na main/master, podczas gdy praca toczy się na feature/support-v2 (301 commitów do przodu) — czyli faktycznie nie chodziło nigdzie. Od 2026-08-21 uruchamiane na push do każdej gałęzi, na PR i ręcznie. Pierwszy zielony przebieg: CI #18, commit e122ae4, 2026-08-21, 2m17s — cztery joby zielone, „API unit tests" wykonane: 37 zestawów, 194 testy, wszystkie przeszły. Poziom dowodu D2 osiągnięty. Przebieg #17 (pierwszy w ogóle) był czerwony na dwóch rzeczach zastanych: zły tag akcji Trivy i apps/www niePrzechodzący typechecku — obie naprawione w e122ae4. | P2: do zrobienia
A3: X-02 | B3: Status wymagany do merge | C3: audyt | D3: X — Infrastruktura jakości | E3: — | F3: 6 | G3: 1 | H3: Faza 0 — Zatrzymać krwawienie | I3: 2026-08-31 | J3: 2026-09-04 | K3: DZIAŁA | L3: ruleset „gałęzie wdrożeniowe — wymagaj zielonego CI" (id 21161479), Active, zakres: gałąź domyślna + live-release-readiness; wymagane 4 checki z ci.yml | M3: — | N3: Funkcja dostępna z panelu klienta bez wychodzenia do DirectAdmina; test uruchamiany w CI. | O3: Wykonane 2026-08-21 w interfejsie GitHuba. Użyty ruleset zamiast klasycznej ochrony gałęzi, bo klasyczny formularz pozwala wybrać wyłącznie checki widziane w ciągu ostatniego tygodnia, a CI nie przebiegło jeszcze ani razu — ruleset przyjmuje check po nazwie. Rozszerzony 2026-08-21 na live-release-readiness — to z niej idą realne wdrożenia, więc ochrona samego main nie pilnowała niczego, co trafia na serwer. Konsekwencja: scalanie na gałąź wdrożeniową przez PR albo fast-forward; lokalny merge commit zostanie zablokowany, bo nie ma własnego przebiegu CI. Obejście: Repository admin (wyjście awaryjne dla jednoosobowego zespołu). Konfiguracja NIE jest w repozytorium — jej jedyny zapis to docs/archiwum/zadania/X-02-status-wymagany-do-merge.md. Poziom dowodu D4. | P3: do zrobienia
A4: X-03 | B4: Testy uruchamiane przed wdrożeniem | C4: audyt | D4: X — Infrastruktura jakości | E4: WYSOKA | F4: 6 | G4: 1 | H4: Faza 0 — Zatrzymać krwawienie | I4: 2026-08-31 | J4: 2026-09-04 | K4: DZIAŁA | L4: .github/workflows/deploy.yml — job test-gate (typecheck + pnpm --filter api test), build-push ma needs: test-gate; ops/scripts/lib/bramka-recznego-wdrozenia.sh — poza Actions odmowa (kod 2) bez WDROZENIE_RECZNE_POWOD (min. 15 znakow), wpis jednoliniowy w /var/log/verris/wdrozenia-reczne.log + syslog verris-wdrozenie; prod-deploy-ghcr.sh / prod-deploy-release.sh / prod-deploy-rolling.sh wolaja bramke przed pierwszym git/docker; deploy.yml eksportuje VERRIS_WDROZENIE_Z_ACTIONS=1 + GITHUB_RUN_ID; test: apps/api/src/test/wdrozenie-reczne-jawne.spec.ts (zachowanie biblioteki + kolejnosc w skryptach) | M4: — | N4: Funkcja dostępna z panelu klienta bez wychodzenia do DirectAdmina; test uruchamiany w CI. | O4: Ścieżka automatyczna (push → build → deploy) od 2026-08-21 nie przepuszcza czerwonych testów. Ścieżka ręczna ops/scripts/prod-deploy-ghcr.sh nadal nie uruchamia żadnych testów — dlatego CZĘŚCIOWE, nie DZIAŁA. | 2026-09-22: sciezka reczna nie jest juz ukryta — jest jawna decyzja z powodem i sladem. Swiadomie NIE blokujemy jej calkiem: to droga awaryjna (rollback, lezacy GitHub). Reczne ustawienie flagi Actions jest mozliwe, ale jest swiadomym klamstwem w poleceniu, nie przeoczeniem. Przy okazji X-13: domyslna galaz w release/rolling zmieniona z porzuconej live-release-readiness na main. D2 2026-09-22: wdrozenie-reczne-jawne.spec.ts zielony lokalnie i w CI #182. Dokumentacja: docs/archiwum/zadania/X-03-testy-uruchamiane-przed-wdrozeniem.md (sekcja 2026-09-22) | P4: do zrobienia
A5: Z-02 | B5: Blokada zamówienia usługi bez opłaty przez klienta | C5: audyt | D5: M — Rozliczenia | E5: — | F5: 6 | G5: 1 | H5: Faza 0 — Zatrzymać krwawienie | I5: 2026-08-31 | J5: 2026-09-04 | K5: DZIAŁA | L5: dto/subscription.dto.ts — @IsIn(CLIENT_PAYMENT_SOURCES); subscriptions.service.ts — ForbiddenException dla MANUAL bez allowManual; test subscriptions.create-guard.spec.ts | M5: — | N5: Funkcja dostępna z panelu klienta bez wychodzenia do DirectAdmina; test uruchamiany w CI. | O5: Zamknięte 2026-08-21 (commit fcf58db). Dwie warstwy: walidacja DTO i twardy warunek w serwisie. Osiem przypadków testowych, sprawdzone też w drugą stronę — na starym kodzie test świeci na czerwono. Dodatkowo @RateLimit 10/h na POST /subscriptions. D2 potwierdzone w CI #18 (2026-08-21): 194 testy zielone, w tym 8 przypadków tego zadania. Dokumentacja: docs/archiwum/zadania/Z-02-blokada-zamowienia-uslugi-bez-oplaty.md | P5: do zrobienia
A6: X-11 | B6: Testy API w osobnym jobie CI, nie za typecheckiem | C6: audyt | D6: X — Infrastruktura jakości | E6: — | F6: 6 | G6: 1 | H6: Faza 0 — Zatrzymać krwawienie | I6: 2026-08-31 | J6: 2026-09-04 | K6: DZIAŁA | L6: .github/workflows/ci.yml — osobny job api-tests o nazwie „API unit tests" | M6: — | N6: Funkcja dostępna z panelu klienta bez wychodzenia do DirectAdmina; test uruchamiany w CI. | O6: Zamknięte 2026-08-21. Zasada: krok, który DOWODZI, nie może stać za krokiem, który tylko sprawdza higienę. Przy przebiegu #17 typecheck wywalił się na apps/www — panelu niezwiązanym z tamtą pracą — i 194 testy nie uruchomiły się ani razu. Koszt rozdzielenia: jeden dodatkowy pnpm install, joby i tak biegną równolegle. deploy.yml celowo zostaje z testami w jednym jobie z typecheckiem, bo zadaniem bramki jest zablokować wdrożenie, a nie dostarczyć dowód. Check „API unit tests" dopisany do rulesetu z X-02 tego samego dnia — bez tego rozdzielenie jobów otwierałoby dziurę: testy widoczne, ale niewymagane do scalenia. Dokumentacja: docs/archiwum/zadania/X-11-testy-api-w-osobnym-jobie.md | KOREKTA 2026-08-22: podział jobów zabrał testom budowanie bibliotek, które wcześniej działo się przy okazji przez pnpm typecheck (Turbo, dependsOn ^build). Job „API unit tests” był przez to CZERWONY od tego commita aż do X-17, mimo że zgłosiłem pozycję jako zamkniętą na podstawie zielonych testów lokalnych. Sam przebieg CI sprawdziłem dopiero przy #56. Wniosek zapisany w X-17: pozycja dotycząca CI nie może być zamknięta bez obejrzenia przebiegu, którego dotyczy. | P6: do zrobienia
A7: X-12 | B7: Skrypty węzła serwowane przez API obecne w obrazie produkcyjnym | C7: audyt | D7: X — Infrastruktura jakości | E7: — | F7: 6 | G7: 1 | H7: Faza 0 — Zatrzymać krwawienie | I7: 2026-08-31 | J7: 2026-09-04 | K7: DZIAŁA | L7: Dockerfile.api — COPY dla 10 skryptów; apps/api/src/test/dockerfile-scripts.spec.ts; D3: 2026-08-21 21:57 — `docker exec <api> ls -la ops/scripts/` na control-plane pokazuje 10 plików, w tym node-php-apply.sh, node-app-install.sh i node-account-restore.sh; D3 na węźle: 2026-09-28 — t1.verris.pl (AlmaLinux/CloudLinux 10, DA 1.710): /agent/tasks/{php-apply,app-install,offsite-restore}/script → 3× 200 z tożsamością węzła (X-Server-Id/X-Server-Token) | M7: — | N7: Funkcja dostępna z panelu klienta bez wychodzenia do DirectAdmina; test uruchamiany w CI. | O7: Nowa klasa błędu, której audyt nie widział: „skrypt jest w repozytorium, ale nie ma go w obrazie". Lokalnie wszystko działa, bo monorepo leży obok; w kontenerze jest tylko to, co wymienia Dockerfile. Brakowały trzy: node-account-restore.sh, node-app-install.sh, node-php-apply.sh. Skutek: trzy rodzaje zadań agenta nie wykonywały się na produkcji, przy zielonych testach i zielonym buildzie. Test statyczny wyciąga ścieżki z loaderów i porównuje z COPY — kosztuje milisekundy, zamyka całą klasę. | D3 OSIĄGNIĘTE 2026-08-21 21:57 po wdrożeniu #62: wszystkie dziesięć skryptów obecne w obrazie na serwerze. To pierwsza pozycja w tym audycie z dowodem poziomu D3. | P7: do zrobienia
A8: X-13 | B8: Jedna gałąź wdrożeniowa — main | C8: audyt | D8: X — Infrastruktura jakości | E8: — | F8: 6 | G8: 1 | H8: Faza 0 — Zatrzymać krwawienie | I8: 2026-08-31 | J8: 2026-09-04 | K8: DZIAŁA | L8: .github/workflows/deploy.yml — on.push.branches: [main] | M8: — | N8: Funkcja dostępna z panelu klienta bez wychodzenia do DirectAdmina; test uruchamiany w CI. | O8: Do 2026-08-21 wdrożenie wyzwalały trzy gałęzie: main, master i live-release-readiness. Realne wdrożenia szły z live-release-readiness, master w repozytorium nie istniał, a main stał od czerwca. Trzy wyzwalacze to trzy odpowiedzi na pytanie „co jest na produkcji" — czyli brak odpowiedzi. Decyzja PM-a: zostaje sam main, chroniony rulesetem z X-02 i bramką testową z X-03. Konsekwencja: live-release-readiness przestaje być gałęzią wdrożeniową i zostaje jako zapis historii do czasu wycofania. | P8: do zrobienia
A9: X-14 | B9: CI sprawdza DANE po migracji, nie tylko czy migracja się wykonała | C9: audyt | D9: X — Infrastruktura jakości | E9: — | F9: 6 | G9: 1 | H9: Faza 0 — Zatrzymać krwawienie | I9: 2026-08-31 | J9: 2026-09-04 | K9: DZIAŁA | L9: .github/workflows/ci.yml — job migrations: kroki „Seed reference data” i „Verify migrated data (Z-12, Z-13, Z-16)”; ops/sql/sprawdz-baze-po-migracji.sql — 5 bloków asercji kończących się RAISE EXCEPTION | M9: — | N9: Funkcja dostępna z panelu klienta bez wychodzenia do DirectAdmina; test uruchamiany w CI. | O9: Zamknięte 2026-08-22. Job migrations sprawdzał wyłącznie, czy migracje dają się zastosować i czy schemat nie ma dryfu. Nie sprawdzał, czy DANE, które migracje wstawiają, tam są i mają właściwe wartości — a Z-12 i Z-13 to migracje danych, których poprawność testy jednostkowe potwierdzały wyłącznie przez czytanie SQL-a jako TEKSTU. | Teraz CI odpytuje bazę: czy plan verris-hosting istnieje z ceną 45,00 brutto i limitami 200/8192/51200, czy publiczny pakiet hostingowy jest dokładnie jeden, czy prototypy są wycofane ale nie zdezaktywowane, czy kolumny overcommit mają NEUTRALNĄ domyślną 1, czy księga pojemności zgadza się z sumą limitów kont żywych. | Sprawdzone na prawdziwym Postgresie 16 ze wszystkimi 100 migracjami: komplet przechodzi, a podmiana ceny na 49,00 i podniesienie domyślnej nadsubskrypcji do 4 wywalają job z kodem 3. | ODKRYTE PRZY TESTOWANIU: na bazie z samych migracji plany prototypowe w ogóle nie istnieją (tworzy je seed), więc asercja o ich wycofaniu przechodziła TRYWIALNIE — w logu CI wygląda to identycznie jak prawdziwe „wszystko w porządku”. Stąd krok seeda przed asercjami plus jawny warunek: zero znalezionych prototypów to błąd, nie sukces. Przy okazji CI po raz pierwszy weryfikuje, że seed w ogóle wykonuje się na świeżej bazie. | Dokumentacja: docs/archiwum/zadania/X-14-asercje-danych-po-migracji.md | P9: do zrobienia
A10: X-15 | B10: Niezmiennik księgi pojemności sprawdzany liczbowo, nie tekstowo | C10: audyt | D10: X — Infrastruktura jakości | E10: — | F10: 6 | G10: 1 | H10: Faza 0 — Zatrzymać krwawienie | I10: 2026-08-31 | J10: 2026-09-04 | K10: DZIAŁA | L10: apps/api/src/subscriptions/ksiega-niezmiennik.spec.ts — 15 testów: losowe ciągi operacji (założenie konta, skalowanie w górę i w dół, zmiana planu, usunięcie) z porównaniem księgi z prawdą po KAŻDYM kroku; node-capacity.ts — deltaKsiegi/limityEfektywne/ksiegaUpdateData jako jedyna arytmetyka księgi w projekcie | M10: — | N10: Funkcja dostępna z panelu klienta bez wychodzenia do DirectAdmina; test uruchamiany w CI. | O10: Zamknięte 2026-08-22. Strażniki z Z-16 były statyczne — czytały tekst źródłowy. Złapią usunięcie linii (i złapały, gdy arytmetyka poszła do wspólnych funkcji), ale nie złapią błędu w ZNAKU delty ani pomylonych argumentów: deltaKsiegi(po, przed) zamiast deltaKsiegi(przed, po) przechodzi każdy test tekstowy i rozjeżdża księgę przy pierwszej operacji. | Test sprawdza jedyną rzecz, która musi być prawdziwa: allocated* równa się sumie limitów efektywnych kont żywych po dowolnym ciągu operacji. Deterministyczny generator, sześć ziaren, sprawdzenie po każdym kroku — żeby dwa błędy nie zniosły się nawzajem. | Uczciwość testu polega na tym, że symulator używa DOKŁADNIE tych samych funkcji co produkcja; gdyby liczył po swojemu, sprawdzałby siebie. Warunkiem było wyciągnięcie arytmetyki z czterech serwisów do node-capacity.ts — przy okazji piąty rozjazd nie ma już gdzie powstać. | Zweryfikowane: odwrócenie znaku w JEDNYM zasobie czerwieni 10 z 15 testów niezmiennika. Test statyczny tego nie widzi. | Czego to nie sprawdza: czy serwisy wołają te funkcje w odpowiednim momencie i z odpowiednimi argumentami — to jest rola X-04. Tu weryfikowana jest arytmetyka, tam okablowanie. | P10: do zrobienia
A11: X-17 | B11: Joby CI budują zależności workspace'u zanim uruchomią testy | C11: audyt | D11: X — Infrastruktura jakości | E11: — | F11: 6 | G11: 1 | H11: Faza 0 — Zatrzymać krwawienie | I11: 2026-08-31 | J11: 2026-09-04 | K11: DZIAŁA | L11: .github/workflows/ci.yml — krok „Build workspace libraries” w jobie api-tests, „Generate Prisma client” w jobie migrations; turbo.json — zadanie test dostaje dependsOn ^build; apps/api/src/test/ci-joby.spec.ts — 6 testów strażnika | M11: — | N11: Funkcja dostępna z panelu klienta bez wychodzenia do DirectAdmina; test uruchamiany w CI. | O11: Zamknięte 2026-08-22 po przejrzeniu przebiegu CI #56. To jest MÓJ błąd i dokładnie ten wzorzec, który X-11 miał naprawiać. | @verris/database ma main: dist/index.js. Bez zbudowanego dist/ jest nie rozwiąże modułu i 32 z 48 zestawów NIE STARTUJĄ — nie failują, tylko się nie uruchamiają. W logu wygląda to jak awaria testów, a jest awarią konfiguracji. | Przed X-11 testy biegły wewnątrz joba static-checks, którego krok pnpm typecheck idzie przez Turbo, a typecheck ma dependsOn ^build. Biblioteki budowały się PRZY OKAZJI — nikt tego nie zaprojektował, więc nikt nie zauważył, gdy zniknęło. X-11 wydzieliło testy do własnego joba, który nie budował niczego; pnpm --filter api test omija Turbo, a zadanie test nie miało dependsOn. | Job był czerwony przez trzy wdrożenia (CI #54, #55, #56) przy 415 zielonych testach na maszynie, gdzie dist/ leżało zbudowane z dawnych uruchomień. Zgłosiłem X-11 jako zamknięte, nie sprawdziwszy przebiegu CI — „zielono lokalnie” potraktowałem jako dowód, a to jest dokładnie ten skrót, przed którym skala dowodowa tego audytu ma chronić. | Drugi błąd, świeższy: krok „Seed reference data” dodany do joba migrations w commicie d381a64 wołał seed importujący @verris/database, a ten job nigdy nie generował klienta. Job przeszedł z zielonego na czerwony. | Poprawka na trzech poziomach: jawne kroki w obu jobach, dependsOn ^build w turbo.json (żeby pnpm test był poprawny też lokalnie i w każdym przyszłym jobie) oraz strażnik, który przemiata ci.yml i zapala się, gdy job uruchamia testy bez zbudowania bibliotek. | Strażnik w pierwszej wersji dał FAŁSZYWY ALARM — wzorzec \bjest\b trafiał w polskie słowo „jest” w moich własnych komentarzach. Zawężony do faktycznych wywołań komend, komentarze odfiltrowane przed dopasowaniem. Narzędzie, którego jedynym zadaniem jest nie kłamać, samo skłamało za pierwszym razem. | Dokumentacja: docs/archiwum/zadania/X-17-joby-ci-buduja-zaleznosci.md | D2 OSIĄGNIĘTE 2026-08-22: przebieg CI #57 zielony w komplecie — sześć jobów, w tym „API integration tests" z Postgresem 16. | P11: do zrobienia
A12: PB-01 | B12: Unit economics węzła vs cena 45 zł/mies. brutto (399 zł/rok) | C12: poza audytem | D12: Praca spoza audytu | E12: BLOKER BIZNESOWY | F12: 8 | G12: 1 | H12: Faza 0 — Zatrzymać krwawienie | I12: 2026-08-31 | J12: 2026-09-04 | K12: — | L12: — | M12: — | N12: Arkusz z kosztem miesięcznym węzła, liczbą kont na węzeł, marżą jednostkową i progiem rentowności. Decyzja: cena zostaje albo się zmienia — zapisana w repo. | O12: Policzyć pełny koszt węzła: serwer + CloudLinux + LiteSpeed + DirectAdmin + Imunify + backup S3 + amortyzacja wsparcia. Wyliczyć próg rentowności w kontach na węzeł i marżę przy 45 zł brutto (36,59 zł netto). | P12: do zrobienia
A13: Z-04 | B13: Guard uprawnień subkont — domyślna odmowa | C13: audyt | D13: O — Multi-user i reseller | E13: — | F13: 6 | G13: 2 | H13: Faza 0 — Zatrzymać krwawienie | I13: 2026-09-07 | J13: 2026-09-11 | K13: DZIAŁA | L13: customer-permissions.guard.ts — typ WymogTrasy, REGULY_TRAS, domyślne 'ODMOWA'; customer-permissions-coverage.spec.ts — 55 tras zamkniętych, lista jawna | M13: — | N13: Funkcja dostępna z panelu klienta bez wychodzenia do DirectAdmina; test uruchamiany w CI. | O13: Zamknięte 2026-08-21. Przemiatanie tras pokazało większą skalę niż pierwotny opis: 148 z 347 tras dostępnych dla konta klienckiego nie wymagało żadnego uprawnienia, w tym POST /me/account-deletion (usunięcie konta właściciela), POST /partners/me/payouts/bank (wypłata prowizji na konto bankowe) i POST /users/iam/invites. Domyślna odpowiedź odwrócona na odmowę; rzeczy właściciela zamknięte twardo, niezależnie od nadanych uprawnień. Testy na zachowaniu strażnika, nie na metadanych — 15 z 28 czerwieniło się na starej wersji. Dokumentacja: docs/archiwum/zadania/Z-04-guard-uprawnien-subkont.md | P13: do zrobienia
... A126: PB-19 | B126: Widok strony: ruch, TTFB, błędy 5xx, technologia i logi z węzła | C126: poza audytem | D126: Praca spoza audytu | E126: ŚREDNI | F126: 24 | G126: 19 | H126: Faza 3 — Wejście na rynek | I126: 2026-11-30 | J126: 2026-12-04 | K126: — | L126: — | M126: — | N126: Na działającym węźle produkcyjnym: widok strony pokazuje ruch 7 dni, TTFB i 5xx z prawdziwych logów, wykrytą technologię i zakładkę „Logi”; brak danych = „—”, nie zero; testy parsera logów i detekcji technologii w CI; sprawdzone na D3 (serwer). | O126: Braki makiety widoku strony (docs/design/wzorzec-panelu.html), których API nie ma, bo wymagają węzła: (1) odwiedziny, mediana TTFB i błędy 5xx per domena z logów serwera WWW przez agenta; (2) rozpoznanie technologii strony (WordPress, PrestaShop, Laravel, HTML, przekierowanie) skanem plików i narzędzia dopasowane do technologii; (3) zakładka „Logi” — log błędów i dostępu per domena. Dziś panel pokazuje tylko to, co realnie istnieje (docs/VERRIS.md, sekcja „Otwarte”). | 2026-09-25 KOD (D2): zadanie SITE_STATS + ops/scripts/node-site-stats.sh — technologia (WordPress/PrestaShop/Joomla/Drupal/Nextcloud/MediaWiki/Laravel/PHP/HTML/domyślna Verris, z wersją) sprawdzana jako klient; ruch 7 dni (żądania, odwiedzający = unikalne IP, 5xx) z logu DirectAdmina /var/log/httpd/domains/<domena>.log (combined), ścieżki bez parametrów; mediana TTFB z 5 żądań z samego serwera (127.0.0.1 + Host). Panel: widok strony → Przegląd → „Ruch i wydajność — 7 dni” (brak logu = „—”), nowa zakładka „Logi” (log dostępu i błędów tej domeny). Testy parsera i detekcji: site-stats.service.spec.ts. ZOSTAJE: D3 na węźle. | P126: do zrobienia
A127: PB-12 | B127: Runbook startu i decyzja GO | C127: poza audytem | D127: Praca spoza audytu | E127: BLOKER BIZNESOWY | F127: 8 | G127: 20 | I127: 2027-01-04 | J127: 2027-01-08 | K127: — | L127: — | M127: PB-05 (decyzja GO po przejściu ścieżki na produkcji) | N127: Każdy z 11 blokerów ma wpis: co zrobiono, gdzie jest dowód, kto potwierdził. Bez formuły „warunkowe GO”. | O127: Domknięcie: przegląd wszystkich blokerów z dowodem zamknięcia, decyzja GO/NO-GO zapisana z datą. | P127: do zrobienia
A128: PB-10 | B128: Kampania gads-search-hosting-202607 — uruchomienie | C128: poza audytem | D128: Praca spoza audytu | E128: ŚREDNI | F128: 8 | G128: 20 | I128: 2027-01-04 | J128: 2027-01-08 | K128: — | L128: — | M128: PB-06 (kampania kieruje na landing) | N128: Kampania utworzona wstrzymana, konwersje podpięte, budżet i stawki ustawione. Start dopiero po PB-05. | O128: Konfiguracja kampanii wyszukiwarkowej, budżet 500–1000 zł/mies., oś przekazu: migracja bez przestoju. | P128: do zrobienia
A129: Z-18 | B129: Prawdziwa przyczyna błędu provisioningu nie ginie po drodze (część) | C129: audyt | D129: Z — Pass adwersaryjny | E129: BLOKER STARTU | F129: 2 | G129: 21 | I129: 2026-11-09 | J129: 2026-11-13 | K129: DZIAŁA | L129: apps/api/src/subscriptions/provisioning-error.ts — BladEtapuProvisioningu (etap, przyczyna, message z doklejoną przyczyną); provisioning-queue.service.ts — kategoriaBledu(err), klasyfikacja obiektu zamiast napisu, pole przyczyna w audycie ponowienia i twardej porażki; provisioning.service.ts — trzy etapy DA (ensureUserPackage, createAccount, setAccountLimits) bez prania przyczyny; apps/api/src/test/blad-provisioningu-nie-klamie.spec.ts (18). BRAK: dowodu D3 — nie ma węzła obliczeniowego, więc ścieżki provisioningu nie da się dziś przejść na produkcji. | M129: — | N129: Funkcja dostępna z panelu klienta bez wychodzenia do DirectAdmina; test uruchamiany w CI. | O129: 2026-09-24 PRZEGLĄD „CZEGO NIE OBEJMUJE” (Stripe, migracje, autoskalowanie + sąsiednie ścieżki pieniędzy): (1) twarda porażka provisioningu kończyła się zwykłym throw — BullMQ ponawiał i zakładał konto po zwrocie środków; teraz UnrecoverableError; (2) 503 z wyboru węzła (polski komunikat) był „trwały” → zwrot przy pierwszej próbie; teraz status HTTP przed prozą; (3) odnowienie portfelem: błąd bazy = PAST_DUE + mail „płatność nieudana”; teraz tylko ConflictException; (4) odnowienie VPS: catch {} + po karencji deleteServer — błąd bazy mógł skasować serwer klienta; (5) usunięcie konta DA (RODO): „Server not found”/„brak …” uznawane za „użytkownika nie ma”; (6) autoskalowanie: brak środków po typie. Stripe (webhooki z ewidencją i ponowieniami) bez zastrzeżeń. 18 testów zachowania. Pozycja nadal czeka na D3 na węźle #1. | Stan 2026-08-23: NAPRAWIONE W KODZIE (D2), POZYCJA OTWARTA — bloker startu do czasu dowodu D3 na węźle #1 (sprint 8). Krytyczność nadana decyzją właściciela produktu 2026-08-23. | JAK TO WYSZŁO: X-30 naprawiło alerting i w ciągu dziesięciu minut zapaliła się pierwsza reguła z PRAWDZIWEGO powodu — VerrisProvisioningQueueFailed. W kolejce leżały cztery martwe joby, a w panelu operatora stało przy nich „DirectAdmin package "starter" is missing on the node and could not be created automatically". W audycie stało co innego: ensureUserPackage / connect ECONNREFUSED 62.238.0.223:2222 (2026-07-07 i 07-10) oraz createAccount / „DirectAdmin API Error: Unable to Create User — A valid IP was not provided" (2026-05-30). Węzeł nie przyjmował połączeń; z pakietem nie było nic nie tak. Same joby są nieszkodliwe — konto testowe właściciela, domeny test.pl/testowa.pl/hvln.pl, sprzed trzech miesięcy, z czasów gdy węzeł testowy jeszcze istniał (dziś nie ma go wcale). Ale komunikat doprowadził mnie do hipotezy o złym mapowaniu planów na pakiety DA — całkowicie chybionej. Na tym polega koszt takiego błędu: nie na tym, że coś nie działa, tylko że wszyscy patrzą nie tam. | MECHANIZM: provisioning.service.ts łapał prawdziwy błąd, zapisywał go do audytu i rzucał dalej STAŁY NAPIS. Prawda zostawała w bazie, w górę szła zmyślona przyczyna. A wyżej: const errCategory = categorizeProvisioningError(msg) — klasyfikator dostawał ten wyprany napis. Jest napisany POPRAWNIE, ma econnrefused na liście błędów przejściowych; tylko nigdy nie widzi tego słowa. | DLACZEGO DOTYKA PIENIĘDZY: przy kliencie i chwilowym zerwaniu sieci — próba 1 → ECONNREFUSED przebrany za brak pakietu → permanent → ścieżka twardej porażki JUŻ PRZY PIERWSZEJ PRÓBIE: subskrypcja na FAILED, ZWROT ŚRODKÓW do portfela, status PENDING_PAYMENT; potem throw err i BullMQ i tak ponawia (attempts: 3, backoff wykładniczy); próba 2 przechodzi, konto powstaje, provisioning.service.ts:299 ustawia subskrypcję na ACTIVE. Klient ma działający hosting i odzyskane pieniądze, a zwrot jest idempotentny (sub-{id}-initial-refund), więc nic go nie cofnie. Wada uśpiona — nie ma dowodu, że się zdarzyła (te joby padły do końca, węzeł był wyłączony na dobre) — ale leży dokładnie na ścieżce pierwszego płacącego klienta. | RODZINA, NOWY WARIANT: to NIE jest „kontrola, która melduje zamiast zatrzymywać" (X-14, X-23, H-19, X-27), gdzie mechanizm istniał i niczego nie bramkował. To POPRAWNA KONTROLA, KTÓREJ SIĘ KŁAMIE: guard dobry, decyzja dobra, lista wyjątków kompletna — a wejście wyprane po drodze. Blisko też rodzinie „strażnik dopasowuje własną prozę" (dziesiąte wystąpienie): jeden z trzech komunikatów był ułożony tak, żeby TRAFIĆ w listę przejściowych — 'CloudLinux LVE limits could not be applied on this node.' kontra lower.includes('cloudlinux lve limits could not be applied'). Działało przypadkiem, dopóki ktoś nie poprawiłby zdania. | POPRAWKA: BladEtapuProvisioningu(etap, przyczyna, komunikatDlaCzlowieka) — klasa niosąca ORYGINALNĄ treść błędu; kategoriaBledu(err) pyta obiekt o przyczynę i dopiero na niej odpala istniejący klasyfikator, a napis zostaje ścieżką zapasową. Przyczyna jest DOKLEJONA także do message, bo panel pokazuje job.failedReason z BullMQ (czyli Error.message), a failedCategory liczy się z tego samego napisu — gdyby przyczyna została tylko we właściwości, panel dalej opowiadałby zmyśloną historię. Audyt dostał osobne pole przyczyna obok error. | Czerwieni się na starym kodzie: 4 z 18. Czternaście przechodziło, bo dotyczą zachowania kategoriaBledu, której przed poprawką nie było — redness siedzi w asercjach strukturalnych. Mówię o tym wprost, żeby „4 z 18" nie wyglądało słabiej, niż jest. | CZEGO NIE OBEJMUJE: innych miejsc, gdzie prawdziwy błąd może być prany (Stripe, migracje, autoskalowanie mają własne bloki catch i nie były przeglądane pod tym kątem — warte osobnego przejścia); sensowności samego zwrotu przy twardej porażce (zwrot jest właściwy, gdy błąd NAPRAWDĘ jest trwały — ta pozycja naprawia rozpoznanie, nie decyzję); czterech martwych jobów w kolejce (sprzątane po tej poprawce, decyzją właściciela produktu, żeby czyścić już na kodzie zapisującym prawdziwą przyczynę). | JAK ZAMKNĄĆ: na węźle #1 uruchomić provisioning, przerwać połączenie do DA w trakcie i pokazać w audycie PONOWIENIE zamiast zwrotu środków, a potem konto założone przy drugiej próbie. Dokumentacja: docs/archiwum/zadania/Z-18-blad-provisioningu-nie-klamie.md | 2026-10-03: D3 na t1 — zerwane połączenie z DA przy zakładaniu (REJECT na :2222 do pierwszej odmowy): przed poprawką jedna odmowa spalała 3 próby w 15 s na otwartym bezpieczniku węzła → twarda porażka (przy portfelu zwrot+FAILED); po 80ef14a (opóźnienie ponowienia > okno bezpiecznika) próba 1 RETRYING, próba 2 po ~2,5 min zakłada konto (z18b.d3.hvln.pl). Admin „Ponów” zeruje teraz licznik prób. | P129: do zrobienia
A130: J-01 | B130: LiteSpeed / serwer o wysokiej wydajności | C130: audyt | D130: J — Wydajność i cache | E130: WYSOKA | F130: 6 | G130: 21 | I130: 2026-11-09 | J130: 2026-11-13 | K130: DZIAŁA | L130: decyzja infrastrukturalna, poza kodem panelu; D3 t1 29.09 (panel klienta, d3.hvln.pl): LiteSpeed Enterprise (Server: LiteSpeed), CacheRoot z profilu [OK], strona główna WordPressa z x-litespeed-cache: hit | M130: — | N130: Funkcja dostępna z panelu klienta bez wychodzenia do DirectAdmina; test uruchamiany w CI. | O130: koszt licencji — pozycja do unit economics | WYCENA 2026-09-19: krytycznosc i naklad uzupelnione przy wznowieniu. Pozycje przepisane 2026-08-28 w ramach X-49 zostaly bez wyceny, przez co nie liczyly sie do budzetu godzin i nie stały w zadnym sprincie. Podstawa wyceny: Stan b.d. — definicja ukonczenia dla b.d. to weryfikacja na produkcji z timestampem (D3), nie implementacja. Wykonalne na wezle #1. | 2026-09-25 (wg oficjalnej dokumentacji LiteSpeed dla DirectAdmin): profil węzła sprawdzał /usr/local/lsws/conf/httpd_config.conf — plik OpenLiteSpeed; na LSWS Enterprise (webserver=litespeed) go nie ma, więc konfiguracja cache nigdy się nie wykonywała. Teraz CacheRoot serwera w /etc/httpd/conf/extra/httpd-includes.conf i vhostów w templates/custom/cust_httpd.CUSTOM.2.pre, potem custombuild rewrite_confs — dokładnie jak w docs.litespeedtech.com/lsws/cp/directadmin/configuration/. D3 na węźle. | P130: do zrobienia
A131: J-04 | B131: HTTP/3 | C131: audyt | D131: J — Wydajność i cache | E131: ŚREDNIA | F131: 6 | G131: 21 | I131: 2026-11-09 | J131: 2026-11-13 | K131: DZIAŁA | L131: poza kodem panelu; D3 t1 29.09 (panel klienta, d3.hvln.pl): brak alt-svc, połączenia po h2 — firewalld nie przepuszczał UDP 443; poprawka 68c7e95 (profil + hardening) czeka na push i profil; D3 t1 29.09 wieczór po profilu: curl -sI https://d3.hvln.pl → alt-svc: h3=":443", LiteSpeed nasłuchuje na UDP 443 (IPv4 i IPv6), firewalld przepuszcza 443/udp | M131: — | N131: Funkcja dostępna z panelu klienta bez wychodzenia do DirectAdmina; test uruchamiany w CI. | O131: 4 z 5 hostingów PL już ma | WYCENA 2026-09-19: krytycznosc i naklad uzupelnione przy wznowieniu. Pozycje przepisane 2026-08-28 w ramach X-49 zostaly bez wyceny, przez co nie liczyly sie do budzetu godzin i nie stały w zadnym sprincie. Podstawa wyceny: Stan b.d. — jak J-01, weryfikacja na wezle #1. | P131: do zrobienia
A132: B-01 | B132: Zmiana wersji PHP dla całego konta | C132: audyt | D132: B — Runtime WWW | E132: — | F132: 6 | G132: 21 | I132: 2026-11-09 | J132: 2026-11-13 | K132: DZIAŁA | L132: services.controller.ts:125; D3 t1 28.09: FAIL — selektor bez alt-php (profil nie instalował els-php-release/alt-phpXX na CL10), panel pokazywał wersję mimo błędu → profil + PHP_APPLY cofa wersję (int: php-odrzucona-zmiana.int-spec.ts); retest po profilu; D3 t1 (d3.hvln.pl) 28.09 23:31: PHP 8.2 dla konta z panelu → strona zwraca 8.2.33 na LiteSpeed (PHP_APPLY zakończone); odrzucona zmiana cofa wersję (int) | M132: — | N132: Funkcja dostępna z panelu klienta bez wychodzenia do DirectAdmina; test uruchamiany w CI. | O132: KOREKTA: pozycja miała stan DZIAŁA na podstawie kodu i kolejki PHP_APPLY. Odkryte 2026-08-21 przy przeglądzie Dockerfile.api: loadery skryptów w API czytają plik z dysku i rzucają wyjątkiem, gdy go nie ma, a obraz produkcyjny kopiował tylko 7 z 10 potrzebnych skryptów. Endpoint /agent/tasks/php-apply/script zwracał 500, więc agent nie miał czego uruchomić — zadanie PHP_APPLY nie mogło się wykonać na produkcji ani razu. Naprawione (COPY + test apps/api/src/test/dockerfile-scripts.spec.ts), ale do czasu potwierdzenia na produkcji stan to CZĘŚCIOWE: kod i testy były zielone przez cały czas, więc D1 i D2 nic tu nie dowodzą — potrzebny D3. | 2026-08-21 21:57: przyczyna wdrożeniowa USUNIĘTA — node-php-apply.sh jest już w obrazie (potwierdzone na serwerze, X-12 D3). Pozycja zostaje CZĘŚCIOWE, bo jej własny dowód wymaga wykonania zadania PHP_APPLY na żywym węźle, a węzła jeszcze nie ma. Do przejścia z części B checklisty D3. | WYCENA 2026-09-19: krytycznosc i naklad uzupelnione przy wznowieniu. Pozycje przepisane 2026-08-28 w ramach X-49 zostaly bez wyceny, przez co nie liczyly sie do budzetu godzin i nie stały w zadnym sprincie. Podstawa wyceny: Zmiana wersji PHP dla calego konta — per domena juz dziala (B-02, S), to ten sam mechanizm o poziom wyzej. | 2026-09-22: przeniesione do sprintu 18 — kod i obraz sa gotowe, zostal wylacznie dowod D3 (PHP_APPLY na zywym wezle). | P132: do zrobienia
A133: PB-02 | B133: Onboarding produkcyjnego węzła #1 (Hetzner AX102) | C133: poza audytem | D133: Praca spoza audytu | E133: WYSOKI | F133: 16 | G133: 21 | I133: 2026-11-09 | J133: 2026-11-13 | K133: — | L133: — | M133: — | N133: Węzeł przechodzi wszystkie 14 checków live-readiness. /etc/verris-backup.conf istnieje, pierwszy backup off-site wykonany i zaraportowany do control-plane. | O133: Pełny przebieg node-onboard-live.sh na docelowym serwerze, z konfiguracją backupu off-site jako krokiem obowiązkowym. | P133: do zrobienia
A134: PB-29 | B134: Węzeł: blokery bezpieczeństwa i stabilności | C134: poza audytem | D134: Praca spoza audytu | E134: KRYTYCZNY | F134: 12 | G134: 21 | I134: 2026-11-09 | J134: 2026-11-13 | K134: — | L134: — | M134: — | N134: Nowy węzeł nie dostaje kont przed zieloną weryfikacją; skrypty przechodzą test na węźle testowym (D3). | O134: Decyzja właściciela 2026-09-26. Węzeł przyjmuje klientów dopiero po pozytywnym onboardzie i weryfikacji (dziś ACTIVE już po zatwierdzeniu w kroku 3 — servers.service.ts:308); wykrywanie CloudLinux przez cldetect zamiast „lve” w nazwie jądra (dokumentacja CloudLinux: od CL9 jądro AlmaLinux); MariaDB 11.8 LTS zamiast 10.6 (EOL 6.07.2026 wg MariaDB.org); klucze licencji poza linkiem instalacyjnym i usuwane z dysku po instalacji; security-watch na każdym węźle; faza DA w API. | 2026-09-26 ZROBIONE W KODZIE: selektor tylko po zielonym raporcie onboardu (POST /agent/tasks/onboard-report) i bez hardened=false; MariaDB 11.4 (mariadb1104 — Governor nie dokumentuje 11.8; poprawione złe słowo kluczowe 11.x); cldetect + /proc/lve; klucze licencji przez POST /secrets (audyt, pamięć), token w nagłówku, sprzątanie po DONE; pakiet onboardu w układzie repo (security-watch na każdym węźle); faza DA. Zostało: przejście na węźle testowym (D3). | P134: do zrobienia
A135: PB-36 | B135: Podpisane skrypty węzła i klucz SSH ograniczony do control-plane | C135: poza audytem | D135: Praca spoza audytu | E135: KRYTYCZNY | F135: 10 | G135: 21 | I135: 2026-11-09 | J135: 2026-11-13 | K135: — | L135: — | M135: — | N135: Niepodpisany/zmieniony skrypt odrzucony przez węzeł; authorized_keys zawiera tylko aktualny klucz z ograniczeniem IP. | O135: Decyzja właściciela 2026-09-26: przed startem. Węzeł uruchamia tylko skrypty podpisane kluczem Verris (przejęte API nie daje roota na flocie); klucz SSH z from= na IP control-plane, stare klucze usuwane (dziś agent co minutę tylko dopisuje klucz). | 2026-09-26 ZROBIONE W KODZIE: podpis Ed25519 każdej odpowiedzi GET /agent/tasks/* (skrypty zadań, pakiety onboardu i strony domyślnej, manifest stosu, konfiguracja kopii, zlecenia, klucz deploy) — podpis obejmuje ścieżkę, id węzła, czas i SHA-256 treści (bez podmiany, przeniesienia na inną ścieżkę/węzeł, powtórki po 5 min). Węzeł pobiera wyłącznie przez /usr/local/bin/verris-fetch (openssl pkeyutl -verify), klucz publiczny przywozi bootstrap / instalacja agenta. Klucz deploy: jeden wpis from="VERRIS_CONTROL_PLANE_IPS" bez przekierowań, poprzedni usuwany (rotacja). API w produkcji nie wystartuje bez VERRIS_SCRIPT_SIGNING_KEY albo z kluczem deploy bez adresów control-plane. Test: prawdziwy verris-fetch vs serwer podpisujący (zmieniona treść / inna ścieżka / inny węzeł / stary podpis / brak podpisu → odrzucone) + smoke na lokalnym API. Do sprawdzenia na D3: openssl na CloudLinux 9, rotacja klucza deploy. | P135: do zrobienia
A136: PB-53 | B136: Fala 3 paneli operatora (przed startem) | C136: poza audytem | D136: Praca spoza audytu | E136: WYSOKI | F136: 194 | G136: 21 | I136: 2026-11-09 | J136: 2026-11-13 | K136: — | L136: — | M136: — | N136: F3.2 i F3.3 wdrożone przed 7.12, pozostałe obowiązkowe moduły przed 11.01 — z testami i dowodem D3 na t1 albo AX102; moduły przesunięte po starcie zapisane w planie z decyzją właściciela. | O136: Plan rozbudowy paneli operatora, Fala 3 (9.11–8.01), łącznie ~224 h, z czego F3.1 (poczta konta i węzła, 30 h) jest wydzielone jako PB-52 + N-14; tutaj 194 h: F3.2 ★ bezpieczeństwo węzła — blokady fail2ban z odblokowaniem i białą listą, malware floty z kwarantanną, trafienia WAF (28 h; decyzja D5: zostajemy przy fail2ban); F3.3 ★ kopie floty i polityka (10 h); F3.4 usługi i logi węzła (18 h); F3.5 pełny cykl życia usługi — anulacja na koniec okresu, data odnowienia, obietnica zapłaty, zmiana właściciela, dodatki, limity custom (30 h); F3.6 rozliczenia: obieg i windykacja — proforma z linkiem do płatności (decyzja D7), zaksięgowanie przelewu, portfel ±, zwrot Stripe, nieudane płatności, przypomnienia (34 h); F3.7 helpdesk II — poczta przychodząca do zgłoszeń przez IMAP (decyzja D6), makra, scalanie, działy, SLA, raporty (50 h); F3.8 komunikacja operacyjna (12 h); F3.9 pulpity per rola (12 h). ★ = przed otwartą betą 7.12. Przed 11.01 muszą być: F3.2 (co najmniej odblokowanie IP), F3.3, F3.5 (anulacja, obietnica zapłaty, daty), F3.6 (obieg wpłaty, nieudane płatności), F3.7 (poczta przychodząca, SLA); mogą zejść po starcie: F3.4, F3.8 (poza mailem serwisowym do klientów węzła) i F3.9. Prognoza pokrycia standardu po Fali 3: ~75%. | 2026-10-11 wdrożone na produkcję (deploy #351) i sprawdzone w panelach: Kopie floty, Złośliwe pliki, Poczta bez klienta (import wyłączony — brak skrzynki), Raporty, Nieudane płatności, Windykacja, SLA 1/8–24/120, komunikaty serwisowe z filtrem white label, pulpity per rola; F3.5 anulacja/cofnięcie na żywo. Poprawki z weryfikacji w paczce poprawki4 (WAF v3, data, Select, „2 2 dni”). | P136: do zrobienia
A137: PB-26 | B137: Otwarte testy (beta) z zaproszonymi użytkownikami | C137: poza audytem | D137: Praca spoza audytu | E137: WYSOKI | F137: 12 | G137: 22 | I137: 2026-12-07 | J137: 2026-12-11 | K137: — | L137: — | M137: — | N137: Minimum 7 dni od pierwszej aktywnej usługi; zero otwartych błędów krytycznych (dane, pieniądze, dostęp); ≥ 80% testerów z działającą stroną bez pomocy wsparcia; poprawki „przed GO” zamknięte. Dopiero potem PB-12. | O137: Prośba właściciela 2026-09-24: przed startem otwarte testy z osobami zaproszonymi przez właściciela, w ramach darmowego kredytu / okresu. Plan: docs/ops/BETA_TESTY.md — 10–20 osób (WordPress do przeniesienia, sklepy, osoby nietechniczne, agencje), kod FIXED_CREDIT 150 K na osobę (1 użycie, 14 dni), scenariusze od rejestracji po odtworzenie kopii i telefon, kanał: zgłoszenia z kategorią Beta. Po naszej stronie: generator kodów, kategoria zgłoszeń, mail zaproszenia, ankieta, widok testerów w panelu admina. | PRZYGOTOWANIE 2026-09-24 (D2): panel admina „Testy (beta)” — zaproszenie tworzy imienny kod BETA-XXXXXX (150 K, 1 użycie, 14 dni) i wysyła mail z instrukcją; lista testerów (stan kodu, konto, aktywne usługi, zgłoszenia Beta); temat „Testy (beta)” w panelu klienta tylko dla testera, znacznik Beta w panelu obsługi. Zostaje: ankieta końcowa (mailem), sama beta po węźle #1. | P137: do zrobienia
A138: PB-05 | B138: Test end-to-end „pierwszy klient” | C138: poza audytem | D138: Praca spoza audytu | E138: BLOKER BIZNESOWY | F138: 16 | G138: 22 | I138: 2026-12-07 | J138: 2026-12-11 | K138: — | L138: — | M138: wszystkie blokery zamknięte (sprint 8) | N138: Zapisany przebieg z timestampami dla każdego kroku — to jest dowód poziomu D3, jedyny w całym projekcie. Każdy nieudany krok wraca do backlogu jako bloker. | O138: Przejście całej ścieżki na produkcji jako realny klient: rejestracja, zakup, płatność, provisioning, migracja strony, wystawienie faktury, KSeF, backup, odtworzenie. | P138: do zrobienia

Sheet Sprinty
A1: Sprint | B1: Od | C1: Do | D1: Faza | E1: Cel sprintu | F1: Zadań | G1: Godzin | H1: Pojemność | I1: Obciążenie | J1: Ryzyko
A2: 1 | B2: 2026-08-31 | C2: 2026-09-04 | D2: Faza 0 — Zatrzymać krwawienie | E2: Zatrzymać krwawienie i włączyć CI | F2: =COUNTIF('Backlog do startu'!$G$2:$G$138,A2) | G2: =SUMIF('Backlog do startu'!$G$2:$G$138,A2,'Backlog do startu'!$F$2:$F$138) | H2: 65 | I2: =IFERROR(G2/H2,0) | J2: PB-01 może wywrócić cenę 45 zł. Dlatego jest w pierwszym sprincie, a nie w ostatnim — wynik zmienia treść cennika w sprincie 15. Sprint urósł o sześć pozycji odkrytych przy włączaniu CI — nie było ich w planie z 2026-08. | PRZEPLANOWANIE 2026-09-19: sprinty 1-3 sa WYKONANE. Ich zawartosc zostaje bez zmian jako zapis historii. Faktyczny przebieg: 2026-08-21 do 2026-08-28, trzy sprinty tresci w szesc dni roboczych, po czym 22 dni przerwy. Daty kalendarzowe w tym pliku licza sie od nowego punktu odniesienia (start=2026-08-31), zeby zgadzaly sie DO PRZODU; dla sprintow 1-3 sa o tydzien przesuniete wobec rzeczywistosci i nie nalezy ich czytac jako zapisu, kiedy ta praca powstala.
A3: 2 | B3: 2026-09-07 | C3: 2026-09-11 | D3: Faza 0 — Zatrzymać krwawienie | E3: Zamknąć luki bezpieczeństwa z passu adwersaryjnego | F3: =COUNTIF('Backlog do startu'!$G$2:$G$138,A3) | G3: =SUMIF('Backlog do startu'!$G$2:$G$138,A3,'Backlog do startu'!$F$2:$F$138) | H3: 65 | I3: =IFERROR(G3/H3,0) | J3: Z-03 dotyka skryptów na węźle — zmiana wymaga przetestowania całej ścieżki migracji, nie tylko walidacji DTO. Sprint urósł o dziesięć pozycji odkrytych w trakcie: podatności, strażniki, bramki wdrożeniowe i awaria kopii bazy (H-23/H-24). Przeciążenie jest prawdziwe i celowo widoczne — praca została wykonana, plan jej nie przewidywał. X-28 doszło jako odpowiedź na pytanie, które zostawiło H-23: dlaczego alarm o braku kopii nie dotarł do nikogo. Odpowiedź — nie miał dokąd; w repo nie było Alertmanagera, a Grafana miała odbiorcę i zero reguł. X-29 wyszło godzinę po X-28 i z tego samego pytania: skoro reguły są w repo, to czy wdrożenie w ogóle je dowozi? Nie dowoziło — wdrożenie restartowało tylko aplikacje, a Prometheus i Grafana czytają konfigurację wyłącznie przy starcie. H-20 wykonane tu, a nie w sprincie 9: awaria kopii z H-23 wymusiła odtworzenie bazy tu i teraz, więc dowód D4 powstał jedenaście sprintów przed terminem. X-30 wyszło przy sprawdzaniu, czy X-29 faktycznie coś zmieniło: reguły były wczytane i żadna się nie liczyła. Trzeci raz tego dnia to samo pytanie — czy to, co wygląda na zrobione, jest zrobione — i trzeci raz odpowiedź brzmiała nie. X-31 domyka dzień: po naprawie X-30 alerty ucichną, a cisza wygląda tak samo jak awaria kanału — więc dokładamy regułę, która pali się zawsze i której brak jest sygnałem. Decyzja właściciela produktu: jeden mail na dobę. Z-18 zamyka dzień tym, od czego wszystko się zaczęło: pierwszy alarm zapalony z prawdziwego powodu pokazał wadę, która przy zerwaniu sieci oddaje klientowi pieniądze za usługę, którą za chwilę wykona. Poprawka jest tutaj, dowód D3 dopiero przy węźle #1. X-32 to ostatnie ogniwo dnia i najkrótsza historia: alarm kazał posprzątać kolejkę, a w produkcie nie było czym jej posprzątać. Zostawało grzebanie w Redisie bez śladu w audycie — czyli dokładnie to, przeciwko czemu powstał cały ten dzień. X-33 dopisało się samo, bo wdrożenie #70 padło na bramce z X-30 przy czternastu działających regułach. Metryka reguł pojawia się dopiero na pierwszym takcie schedulera alertów, a bramka czytała ją sekundę po tym, jak /api/health odpowiedziało — mierzyła szybkość startu i meldowała o poprawności prowizjonowania. Bramka, która potrafi zapalić się na zdrowym systemie, uczy klikać „re-run" i przestaje chronić cokolwiek, więc ten sprint domyka się dopiero tutaj. X-34 dopisało się, bo bramka z X-33 miała własną usterkę: printf | grep -q przy pipefail zwraca błąd DOKŁADNIE WTEDY, GDY METRYKA JEST, o ile odpowiedź przekracza bufor potoku. Bramka nie kłamała o Grafanie — kłamała o własnym odczycie, a strażnik tego nie złapał, bo jego atrapa ważyła 200 bajtów zamiast setek kilobajtów i pracował pod innymi flagami powłoki niż produkcja. | 2026-09-22: Z-18 zdjete z listy tego sprintu (kod zrobiony tutaj, D2) — pozycja otwarta czeka na dowod D3 w sprincie 18, a generator przypisuje pozycje do pierwszego sprintu, w ktorym wystepuje. | 2026-10-10: H-20 przeniesione do sprintu 16 — dowód D4 z 2026-08-23 wygasł po 30 dniach (21.09), pozycja wróciła do CZĘŚCIOWE i do blokerów startu. Praca wykonana w tym sprincie zostaje opisana w macierzy; odnowienie dowodu to PB-54.
A4: 3 | B4: 2026-09-14 | C4: 2026-09-18 | D4: Faza 0 — Zatrzymać krwawienie | E4: Pojemność węzła i plan produkcyjny | F4: =COUNTIF('Backlog do startu'!$G$2:$G$138,A4) | G4: =SUMIF('Backlog do startu'!$G$2:$G$138,A4,'Backlog do startu'!$F$2:$F$138) | H4: 65 | I4: =IFERROR(G4/H4,0) | J4: Sprintu nie było w planie z 2026-08. Dołożony po PB-01, które pokazało, że przy dzisiejszym placemencie na węźle mieści się 16 kont, a próg rentowności przy cenie 45 zł to 58. Dopóki Z-12 jest otwarte, sprzedaż zatrzymuje się na szesnastym koncie niezależnie od popytu — selektor odmówi provisioningu. Z-13 idzie razem, bo bez planu produkcyjnego w bazie nie ma czego umieszczać ani na czym testować nadsubskrypcji. PB-14 zamyka sprint, bo wybór dostawcy przesądza o rentowności bardziej niż cokolwiek innego w tym modelu, a decyzja musi zapaść przed zamówieniem serwera w sprincie 8. AKTUALIZACJA 2026-08-22: Z-12 i Z-13 zamknięte tego samego dnia, a przy nich wyszło Z-16 — autoskalowanie nie pyta węzła o pojemność i nie dowozi sufitu z oferty. Dołożone do tego samego sprintu, bo to trzecia strona tej samej sprawy: pojemność węzła musi być liczona w jednym miejscu, a nie w trzech niezależnych.
A5: 4 | B5: 2026-09-21 | C5: 2026-09-25 | D5: Faza 1 — Rozliczenia i dowód odtworzenia | E5: Wznowienie: odzyskac srodowisko i zatrzymac gnicie | F5: =COUNTIF('Backlog do startu'!$G$2:$G$138,A5) | G5: =SUMIF('Backlog do startu'!$G$2:$G$138,A5,'Backlog do startu'!$F$2:$F$138) | H5: 65 | I5: =IFERROR(G5/H5,0) | J5: Pierwszy sprint po 22 dniach przerwy. Kolejnosc nie jest dowolna: DEV-01 idzie pierwsze, bo po decyzji nr 1 z 2026-08-28 JEDYNA realna bramka przed main jest bramka uruchamiana lokalnie, a ona nie wstanie bez bazy deweloperskiej. DEP-01 rosnie samo — kolejka PR-ow Dependabota powiekszyla sie przez przerwe, a job Security scans wykrywa CVE, ktorych poprawki leza niescalone. P-15 W CALOSCI TUTAJ, nie rozbite na dwa sprinty. Korekta 2026-09-19: zalozenie, ze DPA zalezy od tempa dostawcow, bylo nieprawdziwe — trzy z pieciu obowiazuja z mocy umowy glownej, dwa akceptuje sie kliknieciem w panelu. Praca wlasna to wylacznie Zalacznik 1 do DPA Hetznera. Dzieki temu OSTATNI BLOKER POZA KSeF-em zamyka sie w sprincie 4, a nie w sprincie 10. DEP-02 przeniesione do sprintu 10, zeby zmiescic sie w pojemnosci. | DOLOZONE 2026-09-19: X-50. Bramka podatnosci nie jest checkiem wymaganym w rulesecie i nie jest wolana przez deploy.yml, wiec czerwona bramka nie zatrzymuje ani merge, ani wdrozenia. Wchodzi do sprintu 4, bo jest tania (6 h) i jest warunkiem tego, zeby SEC-07 i cokolwiek pozniejszego mialo gdzie sie zatrzymac. X-03 przeniesione do sprintu 5, zeby zmiescic sie w pojemnosci. | DOLOZONE W TRAKCIE 2026-09-19: X-51 (etykiety) i SEC-08 (dwa CRITICAL RCE w Next.js, odkryte przy pierwszym uruchomieniu bramki podatnosci po przerwie). SEC-07 przeniesione tu ze sprintu 5 — zamkniete tego samego dnia. | 2026-09-22: P-15 przeniesione do bloku dokumentow na koncu planu (decyzja wlasciciela — przed pierwszym klientem, nie teraz). Stripe, AWS, Openprovider i Cloudflare zalatwione; zostaje Hetzner z Zalacznikiem 1.
A6: 5 | B6: 2026-09-28 | C6: 2026-10-02 | D6: Faza 1 — Rozliczenia i dowód odtworzenia | E6: Faktury w programie ksiegowym i bramka wdrozenia | F6: =COUNTIF('Backlog do startu'!$G$2:$G$138,A6) | G6: =SUMIF('Backlog do startu'!$G$2:$G$138,A6,'Backlog do startu'!$F$2:$F$138) | H6: 65 | I6: =IFERROR(G6/H6,0) | J6: FAK-01 NA POCZATKU i jako BLOKER STARTU: decyzja z 2026-09-22 (ADR-2026-09-22) — faktury VAT wystawia program ksiegowy. Panel dzis sam numeruje faktury w transakcji obciazenia portfela, wiec bez przelacznika trybu kazda platnosc dostalaby dwie faktury w dwoch seriach. Dopiero po FAK-01 moga zejsc flagi blokera z M-16 i M-17. PB-13 ZAMKNIETE tego samego dnia — kierunek: integracja z programem ksiegowym po API, na start recznie. PB-14 musi zapasc przed zamowieniem serwera w sprincie 6. X-03 — reczna sciezka wdrozenia omija bramke: zamiana cichego obejscia na jawne, z flaga i zapisanym powodem.
A7: 6 | B7: 2026-10-05 | C7: 2026-10-09 | D7: Faza 1 — Rozliczenia i dowód odtworzenia | E7: Fundament designu i edytor DNS | F7: =COUNTIF('Backlog do startu'!$G$2:$G$138,A7) | G7: =SUMIF('Backlog do startu'!$G$2:$G$138,A7,'Backlog do startu'!$F$2:$F$138) | H7: 65 | I7: =IFERROR(G7/H7,0) | J7: Najpierw system wizualny i jeden ekran-wzorzec do akceptacji — wszystko dalej budujemy juz w nowym stylu. F-01/F-02 (edytor DNS) maja kod z 2026-09-22; D3 przy wezle. | PRZEPLANOWANIE 2026-09-22 (3): decyzja wlasciciela — przed startem design (PB-15/16), asystent v1 (PB-17) i tickety v2 (PB-18); plan wydluza sie o 3 sprinty.
A8: 7 | B8: 2026-10-12 | C8: 2026-10-16 | D8: Faza 1 — Rozliczenia i dowód odtworzenia | E8: Ekrany panelu klienta w nowym designie | F8: =COUNTIF('Backlog do startu'!$G$2:$G$138,A8) | G8: =SUMIF('Backlog do startu'!$G$2:$G$138,A8,'Backlog do startu'!$F$2:$F$138) | H8: 65 | I8: =IFERROR(G8/H8,0) | J8: Przeniesienie ekranow po akceptacji wzorca z PB-15. Ryzyko: zakres — ekranow jest duzo; kolejnosc od najczesciej uzywanych. | PRZEPLANOWANIE 2026-09-22 (3): decyzja wlasciciela — przed startem design (PB-15/16), asystent v1 (PB-17) i tickety v2 (PB-18); plan wydluza sie o 3 sprinty.
A9: 8 | B9: 2026-10-19 | C9: 2026-10-23 | D9: Faza 1 — Rozliczenia i dowód odtworzenia | E9: Poczta: dostarczalnosc i skrzynki | F9: =COUNTIF('Backlog do startu'!$G$2:$G$138,A9) | G9: =SUMIF('Backlog do startu'!$G$2:$G$138,A9,'Backlog do startu'!$F$2:$F$138) | H9: 65 | I9: =IFERROR(G9/H9,0) | J9: Brak SPF/DKIM w panelu to najczestsza przyczyna "moja poczta trafia do spamu". Backend dziala — to glownie podpiecie osieroconego komponentu. | PRZEPLANOWANIE 2026-09-22 (decyzja wlasciciela): wszystko, co wymaga nowego serwera, na koniec — zakup AX102 dopiero w sprincie 18, zeby serwer nie stal pusty i nie generowal kosztow. Najpierw panel, funkcje i poprawki na istniejacej infrastrukturze. | PRZEPLANOWANIE 2026-09-22 (3): decyzja wlasciciela — przed startem design (PB-15/16), asystent v1 (PB-17) i tickety v2 (PB-18); plan wydluza sie o 3 sprinty.
A10: 9 | B10: 2026-10-26 | C10: 2026-10-30 | D10: Faza 2 — Odzyskanie funkcji-widm i luki pierwszego tygodnia | E10: Asystent v1 | F10: =COUNTIF('Backlog do startu'!$G$2:$G$138,A10) | G10: =SUMIF('Backlog do startu'!$G$2:$G$138,A10,'Backlog do startu'!$F$2:$F$138) | H10: 65 | I10: =IFERROR(G10/H10,0) | J10: Dymki na regulach i naprawy odwracalne — bez kosztow AI i bez akcji destrukcyjnych. Agent wykonujacy akcje: po starcie. | PRZEPLANOWANIE 2026-09-22 (3): decyzja wlasciciela — przed startem design (PB-15/16), asystent v1 (PB-17) i tickety v2 (PB-18); plan wydluza sie o 3 sprinty.
A11: 10 | B11: 2026-11-02 | C11: 2026-11-06 | D11: Faza 2 — Odzyskanie funkcji-widm i luki pierwszego tygodnia | E11: Tickety v2 | F11: =COUNTIF('Backlog do startu'!$G$2:$G$138,A11) | G11: =SUMIF('Backlog do startu'!$G$2:$G$138,A11,'Backlog do startu'!$F$2:$F$138) | H11: 65 | I11: =IFERROR(G11/H11,0) | J11: Od pierwszego klienta support musi byc szybki; auto-wysylka odpowiedzi dopiero po zebraniu danych o trafnosci szkicow. | PRZEPLANOWANIE 2026-09-22 (3): decyzja wlasciciela — przed startem design (PB-15/16), asystent v1 (PB-17) i tickety v2 (PB-18); plan wydluza sie o 3 sprinty.
A12: 11 | B12: 2026-11-09 | C12: 2026-11-13 | D12: Faza 2 — Odzyskanie funkcji-widm i luki pierwszego tygodnia | E12: Warstwa operatorska: zatrzymywanie szkody | F12: =COUNTIF('Backlog do startu'!$G$2:$G$138,A12) | G12: =SUMIF('Backlog do startu'!$G$2:$G$138,A12,'Backlog do startu'!$F$2:$F$138) | H12: 65 | I12: =IFERROR(G12/H12,0) | J12: Bez tego pierwszy incydent obslugujesz curlem o drugiej w nocy. Pierwsze cztery pozycje to endpointy, ktore juz dzialaja. | PRZEPLANOWANIE 2026-09-22 (decyzja wlasciciela): wszystko, co wymaga nowego serwera, na koniec — zakup AX102 dopiero w sprincie 18, zeby serwer nie stal pusty i nie generowal kosztow. Najpierw panel, funkcje i poprawki na istniejacej infrastrukturze. | 2026-10-10: N-14 przeniesione do sprintu 17 — audyt paneli operatora (OC-10) wykazał, że kordon działa tylko w module marketingu; decyzja D4: blokada wysyłki konta i kolejka MTA to bloker przed otwartą betą 7.12 (PB-52).
A13: 12 | B13: 2026-11-16 | C13: 2026-11-20 | D13: Faza 2 — Odzyskanie funkcji-widm i luki pierwszego tygodnia | E13: Backup i staging | F13: =COUNTIF('Backlog do startu'!$G$2:$G$138,A13) | G13: =SUMIF('Backlog do startu'!$G$2:$G$138,A13,'Backlog do startu'!$F$2:$F$138) | H13: 65 | I13: =IFERROR(G13/H13,0) | J13: H-17 bylo zalezne od H-20 — zamkniete 2026-08-23 dowodem D4, wiec zaleznosc spelniona. | PRZEPLANOWANIE 2026-09-22 (decyzja wlasciciela): wszystko, co wymaga nowego serwera, na koniec — zakup AX102 dopiero w sprincie 18, zeby serwer nie stal pusty i nie generowal kosztow. Najpierw panel, funkcje i poprawki na istniejacej infrastrukturze. Pozycje, ktore okaza sie wymagac wezla do dowodu D3, dostaja kod tutaj, a dowod w sprincie 18.
... A20: 19 | B20: 2026-11-30 | C20: 2026-12-04 | D20: Faza 3 — Wejście na rynek | E20: Landing i baza wiedzy | F20: =COUNTIF('Backlog do startu'!$G$2:$G$138,A20) | G20: =SUMIF('Backlog do startu'!$G$2:$G$138,A20,'Backlog do startu'!$F$2:$F$138) | H20: 65 | I20: =IFERROR(G20/H20,0) | J20: BLOK DOKUMENTOW — przesuniety na koniec decyzja wlasciciela 2026-09-22: najpierw kod i infrastruktura, dokumenty na sam koniec, przed pierwszym klientem. Kolejnosc wewnatrz bloku wymuszona zaleznosciami: regulamin (PB-03) przed kredytami SLA (N-16), cennik (PB-07) przed landingiem (PB-06), landing przed kampania (PB-10), wszystko przed sciezka pierwszego klienta (PB-05). Landing nie moze obiecywac funkcji ze statusem LUKA lub ATRAPA — kazde zdanie sprawdzic wobec macierzy.
A21: 20 | B21: 2027-01-04 | C21: 2027-01-08 | E21: Decyzja GO i start sprzedaży | F21: =COUNTIF('Backlog do startu'!$G$2:$G$138,A21) | G21: =SUMIF('Backlog do startu'!$G$2:$G$138,A21,'Backlog do startu'!$F$2:$F$138) | H21: 65 | I21: =IFERROR(G21/H21,0) | J21: Kampania powstaje wstrzymana — wlaczenie dopiero po decyzji GO. | PRZEPLANOWANIE 2026-09-22 (decyzja wlasciciela): wszystko, co wymaga nowego serwera, na koniec — zakup AX102 dopiero w sprincie 18, zeby serwer nie stal pusty i nie generowal kosztow. Najpierw panel, funkcje i poprawki na istniejacej infrastrukturze. | 2026-10-04 HARMONOGRAM STARTU (wariant A, decyzja właściciela): decyzja GO 4–8.01.2027 (PB-12), start sprzedaży i kampanii 11.01.2027 (PB-10).
A22: 21 | B22: 2026-11-09 | C22: 2026-11-13 | E22: Wezel produkcyjny #1 (Hetzner AX102) | F22: =COUNTIF('Backlog do startu'!$G$2:$G$138,A22) | G22: =SUMIF('Backlog do startu'!$G$2:$G$138,A22,'Backlog do startu'!$F$2:$F$138) | H22: 65 | I22: =IFERROR(G22/H22,0) | J22: ZAKUP SERWERA TUTAJ, nie wczesniej (decyzja wlasciciela 2026-09-22: bez kosztow za pusty serwer). Zamowienie na poczatku sprintu: AX102 w centrum danych Panelu, licencje DirectAdmin/CloudLinux/Imunify, Storage Box BX21 w innej lokalizacji. NODE-02 ma kod i D2 (instalator zatrzymuje sie na bledzie) — tu dowod D3 przy pierwszym onboardingu. Z-18 dostaje D3 (provisioning z przerwanym polaczeniem do DA) i przestaje byc blokerem. J-01 i J-04 — weryfikacja na wezle z timestampem. | 2026-10-04 HARMONOGRAM STARTU (wariant A, decyzja właściciela): zakup AX102 9.11 zamiast 18.01 — serwer od razu przyjmuje strony właściciela; t1 + AX102 = dwa węzły dla PB-30/32/33 i H-16. | 2026-10-10 PRZECIĄŻENIE ŚWIADOME: PB-53 (Fala 3 paneli operatora, 194 h) rozciąga się na 9.11–8.01; zadanie PB ma jedną liczbę godzin i nie dzieli się na sprinty, więc stoi tu w całości, w sprincie zakupu i onboardingu AX102. Kolejność: moduły ★ (bezpieczeństwo węzła, kopie floty) przed otwartą betą 7.12; cykl życia usługi, obieg wpłat i helpdesk II przed 11.01; usługi i logi węzła, komunikacja i pulpity mogą zejść po starcie. Przy 60–70 h tygodniowo dzielonych z AX102, betą zewnętrzną i KSeF to 4–5 tygodni pracy — jeśli Fala 2 zjedzie do listopada, zagrożony jest termin startu 11.01.
A23: 22 | B23: 2026-12-07 | C23: 2026-12-11 | E23: Beta zewnętrzna i ścieżka pierwszego klienta | F23: =COUNTIF('Backlog do startu'!$G$2:$G$138,A23) | G23: =SUMIF('Backlog do startu'!$G$2:$G$138,A23,'Backlog do startu'!$F$2:$F$138) | H23: 65 | I23: =IFERROR(G23/H23,0) | J23: BLOK DOKUMENTOW — przesuniety na koniec decyzja wlasciciela 2026-09-22: najpierw kod i infrastruktura, dokumenty na sam koniec, przed pierwszym klientem. Kolejnosc wewnatrz bloku wymuszona zaleznosciami: regulamin (PB-03) przed kredytami SLA (N-16), cennik (PB-07) przed landingiem (PB-06), landing przed kampania (PB-10), wszystko przed sciezka pierwszego klienta (PB-05). Kampania powstaje wstrzymana. PB-05 to jedyny moment w planie, w ktorym powstaje dowod D3 calej sciezki — kazdy nieudany krok wraca do backlogu jako bloker i przesuwa start. PB-05 wymaga wezla, dlatego stoi zaraz po sprincie 18. | 2026-09-24: PB-26 (otwarte testy z zaproszonymi osobami) przed PB-05/PB-12 — decyzja GO dopiero po spełnieniu kryteriów końca bety (docs/ops/BETA_TESTY.md). | 2026-10-04 HARMONOGRAM STARTU (wariant A, decyzja właściciela): otwarta beta na AX102 7–20.12 (min. 7 dni), PB-05 na prawdziwych pieniądzach i domenie w jej trakcie; 21.12–3.01 zamrożenie świąteczne, tylko poprawki „przed GO”.
A24: 23 | B24: 2027-01-11 | C24: 2027-01-15 | E24: Po starcie — odłożone decyzją właściciela | F24: =COUNTIF('Backlog do startu'!$G$2:$G$138,A24) | G24: =SUMIF('Backlog do startu'!$G$2:$G$138,A24,'Backlog do startu'!$F$2:$F$138) | H24: 65 | I24: =IFERROR(G24/H24,0) | J24: Poza ścieżką do startu (2027-01-01): pozycje, które właściciel świadomie przesunął na czas po pierwszych klientach. PB-20 (tryb agencji) — decyzja 2026-09-25. | 2026-09-26: PB-20 przeniesione do sprintu 7 — decyzja właściciela z 26.09 („Wszystko teraz, z przełącznikiem kont”), kod gotowy, zostaje przejście na produkcji. | 2026-10-04 HARMONOGRAM STARTU (wariant A, decyzja właściciela): po starcie od 11.01.2027.

Sheet Po starcie
A1: ID | B1: Epik | C1: Nazwa epiku | D1: Kwartał | E1: Priorytet epiku | F1: Funkcja | G1: Kategoria | H1: Krytyczność | I1: h | J1: Stan w kodzie | K1: Dowód / uwagi
A2: B-19 | B2: E-01 | C2: Runtime, pliki i diagnostyka | D2: Q1 2027 | E2: WYSOKI | F2: Kreator stron WWW | G2: B — Runtime WWW | H2: NISKA | I2: 16 | J2: BRAK | K2: SiteBuilderTab.tsx usunięty 2026-09-25
A3: J-05 | B3: E-02 | C3: Wydajność: cache i skalowanie | D3: Q1 2027 | E3: WYSOKI | F3: CDN | G3: J — Wydajność i cache | H3: NISKA | I3: 40 | J3: BRAK | K3: na rynku PL płatny dodatek
A4: J-07 | B4: E-02 | C4: Wydajność: cache i skalowanie | D4: Q1 2027 | E4: WYSOKI | F4: Dedykowany adres IP | G4: J — Wydajność i cache | H4: ŚREDNIA | I4: 6 | J4: CZĘŚCIOWE | K4: addons — jako dodatek typu workorder
A5: H-16 | B5: E-12 | C5: Backup: granularność i retencja | D5: Q1 2027 | E5: WYSOKI | F5: ODTWORZENIE KONTA NA INNY WĘZEŁ | G5: H — Backup i odtwarzanie | H5: WYSOKA | I5: 40 | J5: CZĘŚCIOWE | K5: subscriptions/odtworzenie-na-wezle.service.ts; admin subskrypcja → odtworzenie-na-wezle-panel.tsx; ops/scripts/node-account-restore.sh (OFR_MODE=restore, OFR_SOURCE_PREFIX, OFR_IP); node-tasks.service.ts completeTaskFromNode (przepięcie konta); test odtworzenie-na-wezle.service.spec.ts
